Workbook

Sheet Synthèse
A1: Bouches de ventilation – contrôle par rapport au dossier DCE
A2: EHPAD La Bassée · lot 12 CVC · source : CCTP lot 12 + fichier « Débits par local » (débits du dossier)
A4: Réseau | B4: Fonction | C4: Nombre de bouches | D4: Débit des bouches (m³/h) | E4: Raccordées | F4: À raccorder
A5: CTA 1 | B5: Soufflage | C5: =COUNTIFS(Bouches!$B$2:$B$271,A5,Bouches!$C$2:$C$271,B5) -> 28 | D5: =SUMIFS(Bouches!$M$2:$M$271,Bouches!$B$2:$B$271,A5,Bouches!$C$2:$C$271,B5) -> 2520 | E5: =COUNTIFS(Bouches!$B$2:$B$271,A5,Bouches!$C$2:$C$271,B5,Bouches!$Q$2:$Q$271,"oui") -> 28 | F5: =C5-E5 -> 0
A6: CTA 1 | B6: Extraction | C6: =COUNTIFS(Bouches!$B$2:$B$271,A6,Bouches!$C$2:$C$271,B6) -> 28 | D6: =SUMIFS(Bouches!$M$2:$M$271,Bouches!$B$2:$B$271,A6,Bouches!$C$2:$C$271,B6) -> 2520 | E6: =COUNTIFS(Bouches!$B$2:$B$271,A6,Bouches!$C$2:$C$271,B6,Bouches!$Q$2:$Q$271,"oui") -> 28 | F6: =C6-E6 -> 0
A7: CTA 2 | B7: Soufflage | C7: =COUNTIFS(Bouches!$B$2:$B$271,A7,Bouches!$C$2:$C$271,B7) -> 27 | D7: =SUMIFS(Bouches!$M$2:$M$271,Bouches!$B$2:$B$271,A7,Bouches!$C$2:$C$271,B7) -> 2430 | E7: =COUNTIFS(Bouches!$B$2:$B$271,A7,Bouches!$C$2:$C$271,B7,Bouches!$Q$2:$Q$271,"oui") -> 27 | F7: =C7-E7 -> 0
A8: CTA 2 | B8: Extraction | C8: =COUNTIFS(Bouches!$B$2:$B$271,A8,Bouches!$C$2:$C$271,B8) -> 27 | D8: =SUMIFS(Bouches!$M$2:$M$271,Bouches!$B$2:$B$271,A8,Bouches!$C$2:$C$271,B8) -> 2430 | E8: =COUNTIFS(Bouches!$B$2:$B$271,A8,Bouches!$C$2:$C$271,B8,Bouches!$Q$2:$Q$271,"oui") -> 26 | F8: =C8-E8 -> 1
A9: CTA 3 | B9: Soufflage | C9: =COUNTIFS(Bouches!$B$2:$B$271,A9,Bouches!$C$2:$C$271,B9) -> 13 | D9: =SUMIFS(Bouches!$M$2:$M$271,Bouches!$B$2:$B$271,A9,Bouches!$C$2:$C$271,B9) -> 1170 | E9: =COUNTIFS(Bouches!$B$2:$B$271,A9,Bouches!$C$2:$C$271,B9,Bouches!$Q$2:$Q$271,"oui") -> 12 | F9: =C9-E9 -> 1
A10: CTA 3 | B10: Extraction | C10: =COUNTIFS(Bouches!$B$2:$B$271,A10,Bouches!$C$2:$C$271,B10) -> 13 | D10: =SUMIFS(Bouches!$M$2:$M$271,Bouches!$B$2:$B$271,A10,Bouches!$C$2:$C$271,B10) -> 1170 | E10: =COUNTIFS(Bouches!$B$2:$B$271,A10,Bouches!$C$2:$C$271,B10,Bouches!$Q$2:$Q$271,"oui") -> 13 | F10: =C10-E10 -> 0
A11: CTA 4 | B11: Soufflage | C11: =COUNTIFS(Bouches!$B$2:$B$271,A11,Bouches!$C$2:$C$271,B11) -> 13 | D11: =SUMIFS(Bouches!$M$2:$M$271,Bouches!$B$2:$B$271,A11,Bouches!$C$2:$C$271,B11) -> 1170 | E11: =COUNTIFS(Bouches!$B$2:$B$271,A11,Bouches!$C$2:$C$271,B11,Bouches!$Q$2:$Q$271,"oui") -> 13 | F11: =C11-E11 -> 0
A12: CTA 4 | B12: Extraction | C12: =COUNTIFS(Bouches!$B$2:$B$271,A12,Bouches!$C$2:$C$271,B12) -> 13 | D12: =SUMIFS(Bouches!$M$2:$M$271,Bouches!$B$2:$B$271,A12,Bouches!$C$2:$C$271,B12) -> 1170 | E12: =COUNTIFS(Bouches!$B$2:$B$271,A12,Bouches!$C$2:$C$271,B12,Bouches!$Q$2:$Q$271,"oui") -> 12 | F12: =C12-E12 -> 1
A13: CTA 5 | B13: Soufflage | C13: =COUNTIFS(Bouches!$B$2:$B$271,A13,Bouches!$C$2:$C$271,B13) -> 31 | D13: =SUMIFS(Bouches!$M$2:$M$271,Bouches!$B$2:$B$271,A13,Bouches!$C$2:$C$271,B13) -> 6027 | E13: =COUNTIFS(Bouches!$B$2:$B$271,A13,Bouches!$C$2:$C$271,B13,Bouches!$Q$2:$Q$271,"oui") -> 21 | F13: =C13-E13 -> 10
A14: CTA 5 | B14: Reprise | C14: =COUNTIFS(Bouches!$B$2:$B$271,A14,Bouches!$C$2:$C$271,B14) -> 31 | D14: =SUMIFS(Bouches!$M$2:$M$271,Bouches!$B$2:$B$271,A14,Bouches!$C$2:$C$271,B14) -> 6027 | E14: =COUNTIFS(Bouches!$B$2:$B$271,A14,Bouches!$C$2:$C$271,B14,Bouches!$Q$2:$Q$271,"oui") -> 13 | F14: =C14-E14 -> 18
A15: VMC sanitaires | B15: Extraction | C15: =COUNTIFS(Bouches!$B$2:$B$271,A15,Bouches!$C$2:$C$271,B15) -> 46 | D15: =SUMIFS(Bouches!$M$2:$M$271,Bouches!$B$2:$B$271,A15,Bouches!$C$2:$C$271,B15) -> 3090 | E15: =COUNTIFS(Bouches!$B$2:$B$271,A15,Bouches!$C$2:$C$271,B15,Bouches!$Q$2:$Q$271,"oui") -> 46 | F15: =C15-E15 -> 0
A16: Total | C16: =SUM(C5:C15) -> 270 | D16: =SUM(D5:D15) -> 29724 | E16: =SUM(E5:E15) -> 239 | F16: =SUM(F5:F15) -> 31
A18: Locaux ventilés du dossier | D18: =COUNTA('Contrôle DCE'!$A$2:$A$245) -> 244
A19: dont conformes (débit maquette = débit dossier) | D19: =COUNTIF('Contrôle DCE'!$N$2:$N$245,"oui") -> 244
A21: À retenir
A22: • Chaque local ventilé du dossier a ses bouches, au bon débit (onglet « Contrôle DCE »).
A23: • Les modèles suivent le CCTP : GADD F (chambres), ALYZE S (salles de bains et VMC), DCFD-F et DATP (locaux communs).
A24: • Écarts assumés et suite à donner : onglet « Écarts au CCTP » (flexibles, régulateurs, débit CTA 5, grilles de transfert des offices).

Sheet Bouches
A1: Repère | B1: Réseau | C1: Fonction | D1: Niveau | E1: N° local | F1: Local | G1: Pose | H1: Modèle (CCTP) | I1: Produit | J1: Réf. CCTP | K1: Col L (mm) | L1: Col H (mm) | M1: Débit (m³/h) | N1: Section col (m²) | O1: Vitesse au col (m/s) | P1: Vitesse ≤ maxi ? | Q1: Raccordée | R1: Remarque | S1: Clé local
A2: B016 | B2: CTA 1 | C2: Extraction | D2: N00 | E2: HEB01O | F2: sdb | G2: plafond | H2: VIM ALYZE S | I2: Bouche d'extraction autoréglable | J2: CCTP 4.10.6 | K2: 200 | L2: 60 | M2: 90 | N2: =K2*L2/1000000 -> 0.012 | O2: =M2/3600/N2 -> 2.0833333 | P2: =IF(O2<=Hypothèses!$B$3,"oui","NON") -> oui | Q2: oui | S2: L073
A3: B019 | B3: CTA 1 | C3: Extraction | D3: N00 | E3: HEB01C | F3: sdb | G3: plafond | H3: VIM ALYZE S | I3: Bouche d'extraction autoréglable | J3: CCTP 4.10.6 | K3: 200 | L3: 60 | M3: 90 | N3: =K3*L3/1000000 -> 0.012 | O3: =M3/3600/N3 -> 2.0833333 | P3: =IF(O3<=Hypothèses!$B$3,"oui","NON") -> oui | Q3: oui | S3: L060
A4: B023 | B4: CTA 1 | C4: Extraction | D4: N00 | E4: HEB01R | F4: sdb | G4: plafond | H4: VIM ALYZE S | I4: Bouche d'extraction autoréglable | J4: CCTP 4.10.6 | K4: 200 | L4: 60 | M4: 90 | N4: =K4*L4/1000000 -> 0.012 | O4: =M4/3600/N4 -> 2.0833333 | P4: =IF(O4<=Hypothèses!$B$3,"oui","NON") -> oui | Q4: oui | S4: L076
A5: B024 | B5: CTA 1 | C5: Extraction | D5: N00 | E5: HEB01U | F5: sdb | G5: plafond | H5: VIM ALYZE S | I5: Bouche d'extraction autoréglable | J5: CCTP 4.10.6 | K5: 200 | L5: 60 | M5: 90 | N5: =K5*L5/1000000 -> 0.012 | O5: =M5/3600/N5 -> 2.0833333 | P5: =IF(O5<=Hypothèses!$B$3,"oui","NON") -> oui | Q5: oui | S5: L079
A6: B025 | B6: CTA 1 | C6: Extraction | D6: N00 | E6: HEB01W | F6: sdb | G6: plafond | H6: VIM ALYZE S | I6: Bouche d'extraction autoréglable | J6: CCTP 4.10.6 | K6: 200 | L6: 60 | M6: 90 | N6: =K6*L6/1000000 -> 0.012 | O6: =M6/3600/N6 -> 2.0833333 | P6: =IF(O6<=Hypothèses!$B$3,"oui","NON") -> oui | Q6: oui | S6: L081
A7: B037 | B7: CTA 1 | C7: Extraction | D7: N00 | E7: HEB01CC | F7: sdb | G7: plafond | H7: VIM ALYZE S | I7: Bouche d'extraction autoréglable | J7: CCTP 4.10.6 | K7: 200 | L7: 60 | M7: 90 | N7: =K7*L7/1000000 -> 0.012 | O7: =M7/3600/N7 -> 2.0833333 | P7: =IF(O7<=Hypothèses!$B$3,"oui","NON") -> oui | Q7: oui | S7: L061
A8: B038 | B8: CTA 1 | C8: Extraction | D8: N00 | E8: HEB01P | F8: sdb | G8: plafond | H8: VIM ALYZE S | I8: Bouche d'extraction autoréglable | J8: CCTP 4.10.6 | K8: 200 | L8: 60 | M8: 90 | N8: =K8*L8/1000000 -> 0.012 | O8: =M8/3600/N8 -> 2.0833333 | P8: =IF(O8<=Hypothèses!$B$3,"oui","NON") -> oui | Q8: oui | S8: L074
A9: B119 | B9: CTA 1 | C9: Extraction | D9: N00 | E9: HEB01H | F9: sdb | G9: plafond | H9: VIM ALYZE S | I9: Bouche d'extraction autoréglable | J9: CCTP 4.10.6 | K9: 200 | L9: 60 | M9: 90 | N9: =K9*L9/1000000 -> 0.012 | O9: =M9/3600/N9 -> 2.0833333 | P9: =IF(O9<=Hypothèses!$B$3,"oui","NON") -> oui | Q9: oui | S9: L066
A10: B143 | B10: CTA 1 | C10: Extraction | D10: N00 | E10: HEB01K | F10: sdb | G10: plafond | H10: VIM ALYZE S | I10: Bouche d'extraction autoréglable | J10: CCTP 4.10.6 | K10: 200 | L10: 60 | M10: 90 | N10: =K10*L10/1000000 -> 0.012 | O10: =M10/3600/N10 -> 2.0833333 | P10: =IF(O10<=Hypothèses!$B$3,"oui","NON") -> oui | Q10: oui | S10: L069
A11: B150 | B11: CTA 1 | C11: Extraction | D11: N00 | E11: HEB01D | F11: sdb | G11: plafond | H11: VIM ALYZE S | I11: Bouche d'extraction autoréglable | J11: CCTP 4.10.6 | K11: 200 | L11: 60 | M11: 90 | N11: =K11*L11/1000000 -> 0.012 | O11: =M11/3600/N11 -> 2.0833333 | P11: =IF(O11<=Hypothèses!$B$3,"oui","NON") -> oui | Q11: oui | S11: L062
A12: B166 | B12: CTA 1 | C12: Extraction | D12: N00 | E12: HEB01L | F12: sdb | G12: plafond | H12: VIM ALYZE S | I12: Bouche d'extraction autoréglable | J12: CCTP 4.10.6 | K12: 200 | L12: 60 | M12: 90 | N12: =K12*L12/1000000 -> 0.012 | O12: =M12/3600/N12 -> 2.0833333 | P12: =IF(O12<=Hypothèses!$B$3,"oui","NON") -> oui | Q12: oui | S12: L070
A13: B174 | B13: CTA 1 | C13: Extraction | D13: N00 | E13: HEB01F | F13: sdb | G13: plafond | H13: VIM ALYZE S | I13: Bouche d'extraction autoréglable | J13: CCTP 4.10.6 | K13: 200 | L13: 60 | M13: 90 | N13: =K13*L13/1000000 -> 0.012 | O13: =M13/3600/N13 -> 2.0833333 | P13: =IF(O13<=Hypothèses!$B$3,"oui","NON") -> oui | Q13: oui | S13: L064
... A83: B169 | B83: CTA 2 | C83: Extraction | D83: N01 | E83: HEB01YY | F83: sdb | G83: plafond | H83: VIM ALYZE S | I83: Bouche d'extraction autoréglable | J83: CCTP 4.10.6 | K83: 200 | L83: 60 | M83: 90 | N83: =K83*L83/1000000 -> 0.012 | O83: =M83/3600/N83 -> 2.0833333 | P83: =IF(O83<=Hypothèses!$B$3,"oui","NON") -> oui | Q83: oui | S83: L243
A84: B369 | B84: CTA 2 | C84: Extraction | D84: N01 | E84: HEB01WW | F84: sdb | G84: plafond | H84: VIM ALYZE S | I84: Bouche d'extraction autoréglable | J84: CCTP 4.10.6 | K84: 200 | L84: 60 | M84: 90 | N84: =K84*L84/1000000 -> 0.012 | O84: =M84/3600/N84 -> 2.0833333 | P84: =IF(O84<=Hypothèses!$B$3,"oui","NON") -> oui | Q84: non | R84: Antenne trop courte entre deux raccords | S84: L241
A85: B129 | B85: CTA 2 | C85: Soufflage | D85: N00 | E85: HEB01 | F85: ch. bariatrique | G85: mural | H85: VIM GADD F | I85: Grille murale double déflexion + régulateur de débit constant | J85: CCTP 4.10.6 | K85: 200 | L85: 60 | M85: 90 | N85: =K85*L85/1000000 -> 0.012 | O85: =M85/3600/N85 -> 2.0833333 | P85: =IF(O85<=Hypothèses!$B$3,"oui","NON") -> oui | Q85: oui | S85: L020
A86: B132 | B86: CTA 2 | C86: Soufflage | D86: N00 | E86: HEB01 | F86: ch. bariatrique | G86: mural | H86: VIM GADD F | I86: Grille murale double déflexion + régulateur de débit constant | J86: CCTP 4.10.6 | K86: 200 | L86: 60 | M86: 90 | N86: =K86*L86/1000000 -> 0.012 | O86: =M86/3600/N86 -> 2.0833333 | P86: =IF(O86<=Hypothèses!$B$3,"oui","NON") -> oui | Q86: oui | S86: L021
A87: B133 | B87: CTA 2 | C87: Soufflage | D87: N00 | E87: HEB01 | F87: ch. bariatrique | G87: mural | H87: VIM GADD F | I87: Grille murale double déflexion + régulateur de débit constant | J87: CCTP 4.10.6 | K87: 200 | L87: 60 | M87: 90 | N87: =K87*L87/1000000 -> 0.012 | O87: =M87/3600/N87 -> 2.0833333 | P87: =IF(O87<=Hypothèses!$B$3,"oui","NON") -> oui | Q87: oui | S87: L022
A88: B145 | B88: CTA 2 | C88: Soufflage | D88: N00 | E88: HEB01 | F88: ch. bariatrique | G88: mural | H88: VIM GADD F | I88: Grille murale double déflexion + régulateur de débit constant | J88: CCTP 4.10.6 | K88: 200 | L88: 60 | M88: 90 | N88: =K88*L88/1000000 -> 0.012 | O88: =M88/3600/N88 -> 2.0833333 | P88: =IF(O88<=Hypothèses!$B$3,"oui","NON") -> oui | Q88: oui | S88: L019
A89: B066 | B89: CTA 2 | C89: Soufflage | D89: N00 | E89: HEB01 | F89: ch. couple | G89: mural | H89: VIM GADD F | I89: Grille murale double déflexion + régulateur de débit constant | J89: CCTP 4.10.6 | K89: 200 | L89: 60 | M89: 90 | N89: =K89*L89/1000000 -> 0.012 | O89: =M89/3600/N89 -> 2.0833333 | P89: =IF(O89<=Hypothèses!$B$3,"oui","NON") -> oui | Q89: oui | S89: L025
A90: B069 | B90: CTA 2 | C90: Soufflage | D90: N00 | E90: HEB01 | F90: ch. couple | G90: mural | H90: VIM GADD F | I90: Grille murale double déflexion + régulateur de débit constant | J90: CCTP 4.10.6 | K90: 200 | L90: 60 | M90: 90 | N90: =K90*L90/1000000 -> 0.012 | O90: =M90/3600/N90 -> 2.0833333 | P90: =IF(O90<=Hypothèses!$B$3,"oui","NON") -> oui | Q90: oui | S90: L026
A91: B095 | B91: CTA 2 | C91: Soufflage | D91: N00 | E91: HEB01 | F91: ch. couple | G91: mural | H91: VIM GADD F | I91: Grille murale double déflexion + régulateur de débit constant | J91: CCTP 4.10.6 | K91: 200 | L91: 60 | M91: 90 | N91: =K91*L91/1000000 -> 0.012 | O91: =M91/3600/N91 -> 2.0833333 | P91: =IF(O91<=Hypothèses!$B$3,"oui","NON") -> oui | Q91: oui | S91: L027
A92: B103 | B92: CTA 2 | C92: Soufflage | D92: N00 | E92: HEB01 | F92: ch. couple | G92: mural | H92: VIM GADD F | I92: Grille murale double déflexion + régulateur de débit constant | J92: CCTP 4.10.6 | K92: 200 | L92: 60 | M92: 90 | N92: =K92*L92/1000000 -> 0.012 | O92: =M92/3600/N92 -> 2.0833333 | P92: =IF(O92<=Hypothèses!$B$3,"oui","NON") -> oui | Q92: oui | S92: L028
A93: B065 | B93: CTA 2 | C93: Soufflage | D93: N00 | E93: HEB01 | F93: chambre | G93: mural | H93: VIM GADD F | I93: Grille murale double déflexion + régulateur de débit constant | J93: CCTP 4.10.6 | K93: 200 | L93: 60 | M93: 90 | N93: =K93*L93/1000000 -> 0.012 | O93: =M93/3600/N93 -> 2.0833333 | P93: =IF(O93<=Hypothèses!$B$3,"oui","NON") -> oui | Q93: oui | S93: L037
A94: B107 | B94: CTA 2 | C94: Soufflage | D94: N00 | E94: HEB01 | F94: chambre | G94: mural | H94: VIM GADD F | I94: Grille murale double déflexion + régulateur de débit constant | J94: CCTP 4.10.6 | K94: 200 | L94: 60 | M94: 90 | N94: =K94*L94/1000000 -> 0.012 | O94: =M94/3600/N94 -> 2.0833333 | P94: =IF(O94<=Hypothèses!$B$3,"oui","NON") -> oui | Q94: oui | S94: L041
A95: B108 | B95: CTA 2 | C95: Soufflage | D95: N00 | E95: HEB01 | F95: chambre | G95: mural | H95: VIM GADD F | I95: Grille murale double déflexion + régulateur de débit constant | J95: CCTP 4.10.6 | K95: 200 | L95: 60 | M95: 90 | N95: =K95*L95/1000000 -> 0.012 | O95: =M95/3600/N95 -> 2.0833333 | P95: =IF(O95<=Hypothèses!$B$3,"oui","NON") -> oui | Q95: oui | S95: L044
A96: B130 | B96: CTA 2 | C96: Soufflage | D96: N00 | E96: HEB01 | F96: chambre | G96: mural | H96: VIM GADD F | I96: Grille murale double déflexion + régulateur de débit constant | J96: CCTP 4.10.6 | K96: 200 | L96: 60 | M96: 90 | N96: =K96*L96/1000000 -> 0.012 | O96: =M96/3600/N96 -> 2.0833333 | P96: =IF(O96<=Hypothèses!$B$3,"oui","NON") -> oui | Q96: oui | S96: L042
... A136: B391 | B136: CTA 3 | C136: Soufflage | D136: N01 | E136: HEB01 | F136: chambre | G136: mural | H136: VIM GADD F | I136: Grille murale double déflexion + régulateur de débit constant | J136: CCTP 4.10.6 | K136: 200 | L136: 60 | M136: 90 | N136: =K136*L136/1000000 -> 0.012 | O136: =M136/3600/N136 -> 2.0833333 | P136: =IF(O136<=Hypothèses!$B$3,"oui","NON") -> oui | Q136: oui | S136: L124
A137: B398 | B137: CTA 3 | C137: Soufflage | D137: N01 | E137: HEB01 | F137: chambre | G137: mural | H137: VIM GADD F | I137: Grille murale double déflexion + régulateur de débit constant | J137: CCTP 4.10.6 | K137: 200 | L137: 60 | M137: 90 | N137: =K137*L137/1000000 -> 0.012 | O137: =M137/3600/N137 -> 2.0833333 | P137: =IF(O137<=Hypothèses!$B$3,"oui","NON") -> oui | Q137: non | R137: Antenne trop courte entre deux raccords | S137: L138
A138: B322 | B138: CTA 4 | C138: Extraction | D138: N01 | E138: HEB01BBB | F138: sdb | G138: plafond | H138: VIM ALYZE S | I138: Bouche d'extraction autoréglable | J138: CCTP 4.10.6 | K138: 200 | L138: 60 | M138: 90 | N138: =K138*L138/1000000 -> 0.012 | O138: =M138/3600/N138 -> 2.0833333 | P138: =IF(O138<=Hypothèses!$B$3,"oui","NON") -> oui | Q138: oui | S138: L219
A139: B325 | B139: CTA 4 | C139: Extraction | D139: N01 | E139: HEB01KKK | F139: sdb | G139: plafond | H139: VIM ALYZE S | I139: Bouche d'extraction autoréglable | J139: CCTP 4.10.6 | K139: 200 | L139: 60 | M139: 90 | N139: =K139*L139/1000000 -> 0.012 | O139: =M139/3600/N139 -> 2.0833333 | P139: =IF(O139<=Hypothèses!$B$3,"oui","NON") -> oui | Q139: oui | S139: L163
A140: B326 | B140: CTA 4 | C140: Extraction | D140: N01 | E140: HEB01LLL | F140: sdb | G140: plafond | H140: VIM ALYZE S | I140: Bouche d'extraction autoréglable | J140: CCTP 4.10.6 | K140: 200 | L140: 60 | M140: 90 | N140: =K140*L140/1000000 -> 0.012 | O140: =M140/3600/N140 -> 2.0833333 | P140: =IF(O140<=Hypothèses!$B$3,"oui","NON") -> oui | Q140: oui | S140: L164
A141: B327 | B141: CTA 4 | C141: Extraction | D141: N01 | E141: HEB01NNN | F141: sdb | G141: plafond | H141: VIM ALYZE S | I141: Bouche d'extraction autoréglable | J141: CCTP 4.10.6 | K141: 200 | L141: 60 | M141: 90 | N141: =K141*L141/1000000 -> 0.012 | O141: =M141/3600/N141 -> 2.0833333 | P141: =IF(O141<=Hypothèses!$B$3,"oui","NON") -> oui | Q141: oui | S141: L166
A142: B328 | B142: CTA 4 | C142: Extraction | D142: N01 | E142: HEB01OOO | F142: sdb | G142: plafond | H142: VIM ALYZE S | I142: Bouche d'extraction autoréglable | J142: CCTP 4.10.6 | K142: 200 | L142: 60 | M142: 90 | N142: =K142*L142/1000000 -> 0.012 | O142: =M142/3600/N142 -> 2.0833333 | P142: =IF(O142<=Hypothèses!$B$3,"oui","NON") -> oui | Q142: oui | S142: L167
A143: B329 | B143: CTA 4 | C143: Extraction | D143: N01 | E143: HEB01PPP | F143: sdb | G143: plafond | H143: VIM ALYZE S | I143: Bouche d'extraction autoréglable | J143: CCTP 4.10.6 | K143: 200 | L143: 60 | M143: 90 | N143: =K143*L143/1000000 -> 0.012 | O143: =M143/3600/N143 -> 2.0833333 | P143: =IF(O143<=Hypothèses!$B$3,"oui","NON") -> oui | Q143: oui | S143: L168
A144: B331 | B144: CTA 4 | C144: Extraction | D144: N01 | E144: HEB01III | F144: sdb | G144: plafond | H144: VIM ALYZE S | I144: Bouche d'extraction autoréglable | J144: CCTP 4.10.6 | K144: 200 | L144: 60 | M144: 90 | N144: =K144*L144/1000000 -> 0.012 | O144: =M144/3600/N144 -> 2.0833333 | P144: =IF(O144<=Hypothèses!$B$3,"oui","NON") -> oui | Q144: oui | S144: L161
A145: B354 | B145: CTA 4 | C145: Extraction | D145: N01 | E145: HEB01HHH | F145: sdb | G145: plafond | H145: VIM ALYZE S | I145: Bouche d'extraction autoréglable | J145: CCTP 4.10.6 | K145: 200 | L145: 60 | M145: 90 | N145: =K145*L145/1000000 -> 0.012 | O145: =M145/3600/N145 -> 2.0833333 | P145: =IF(O145<=Hypothèses!$B$3,"oui","NON") -> oui | Q145: oui | S145: L160
A146: B363 | B146: CTA 4 | C146: Extraction | D146: N01 | E146: HEB01UUU | F146: sdb | G146: plafond | H146: VIM ALYZE S | I146: Bouche d'extraction autoréglable | J146: CCTP 4.10.6 | K146: 200 | L146: 60 | M146: 90 | N146: =K146*L146/1000000 -> 0.012 | O146: =M146/3600/N146 -> 2.0833333 | P146: =IF(O146<=Hypothèses!$B$3,"oui","NON") -> oui | Q146: oui | S146: L173
A147: B370 | B147: CTA 4 | C147: Extraction | D147: N01 | E147: HEB01JJJ | F147: sdb | G147: plafond | H147: VIM ALYZE S | I147: Bouche d'extraction autoréglable | J147: CCTP 4.10.6 | K147: 200 | L147: 60 | M147: 90 | N147: =K147*L147/1000000 -> 0.012 | O147: =M147/3600/N147 -> 2.0833333 | P147: =IF(O147<=Hypothèses!$B$3,"oui","NON") -> oui | Q147: oui | S147: L162
A148: B374 | B148: CTA 4 | C148: Extraction | D148: N01 | E148: HEB01BBBB | F148: sdb | G148: plafond | H148: VIM ALYZE S | I148: Bouche d'extraction autoréglable | J148: CCTP 4.10.6 | K148: 200 | L148: 60 | M148: 90 | N148: =K148*L148/1000000 -> 0.012 | O148: =M148/3600/N148 -> 2.0833333 | P148: =IF(O148<=Hypothèses!$B$3,"oui","NON") -> oui | Q148: oui | S148: L154
...

Sheet Contrôle DCE
A1: Clé local | B1: Niveau | C1: N° local | D1: Local | E1: Type de local | F1: Réseau (dossier) | G1: Soufflage dossier (m³/h) | H1: Extraction dossier (m³/h) | I1: Soufflage maquette (m³/h) | J1: Reprise maquette (m³/h) | K1: Extraction maquette (m³/h) | L1: Nb de bouches | M1: Bouches raccordées | N1: Conforme ? | O1: Remarque | P1: Repères des bouches
A2: L019 | B2: N00 | C2: HEB01 | D2: ch. bariatrique | E2: CHAMBRE | F2: CTA 1-2 Héb. ouvert | G2: 90 | H2: 0 | I2: =SUMIFS(Bouches!$M$2:$M$271,Bouches!$S$2:$S$271,A2,Bouches!$C$2:$C$271,"Soufflage") -> 90 | J2: =SUMIFS(Bouches!$M$2:$M$271,Bouches!$S$2:$S$271,A2,Bouches!$C$2:$C$271,"Reprise") -> 0 | K2: =SUMIFS(Bouches!$M$2:$M$271,Bouches!$S$2:$S$271,A2,Bouches!$C$2:$C$271,"Extraction") -> 0 | L2: 1 | M2: 1 | N2: =IF(AND(OR(G2<Hypothèses!$B$6,ABS(I2-G2)<=2),ABS(K2-H2)<=2),"oui","NON") -> oui | P2: B145
A3: L020 | B3: N00 | C3: HEB01 | D3: ch. bariatrique | E3: CHAMBRE | F3: CTA 1-2 Héb. ouvert | G3: 90 | H3: 0 | I3: =SUMIFS(Bouches!$M$2:$M$271,Bouches!$S$2:$S$271,A3,Bouches!$C$2:$C$271,"Soufflage") -> 90 | J3: =SUMIFS(Bouches!$M$2:$M$271,Bouches!$S$2:$S$271,A3,Bouches!$C$2:$C$271,"Reprise") -> 0 | K3: =SUMIFS(Bouches!$M$2:$M$271,Bouches!$S$2:$S$271,A3,Bouches!$C$2:$C$271,"Extraction") -> 0 | L3: 1 | M3: 1 | N3: =IF(AND(OR(G3<Hypothèses!$B$6,ABS(I3-G3)<=2),ABS(K3-H3)<=2),"oui","NON") -> oui | P3: B129
A4: L021 | B4: N00 | C4: HEB01 | D4: ch. bariatrique | E4: CHAMBRE | F4: CTA 1-2 Héb. ouvert | G4: 90 | H4: 0 | I4: =SUMIFS(Bouches!$M$2:$M$271,Bouches!$S$2:$S$271,A4,Bouches!$C$2:$C$271,"Soufflage") -> 90 | J4: =SUMIFS(Bouches!$M$2:$M$271,Bouches!$S$2:$S$271,A4,Bouches!$C$2:$C$271,"Reprise") -> 0 | K4: =SUMIFS(Bouches!$M$2:$M$271,Bouches!$S$2:$S$271,A4,Bouches!$C$2:$C$271,"Extraction") -> 0 | L4: 1 | M4: 1 | N4: =IF(AND(OR(G4<Hypothèses!$B$6,ABS(I4-G4)<=2),ABS(K4-H4)<=2),"oui","NON") -> oui | P4: B132
A5: L022 | B5: N00 | C5: HEB01 | D5: ch. bariatrique | E5: CHAMBRE | F5: CTA 1-2 Héb. ouvert | G5: 90 | H5: 0 | I5: =SUMIFS(Bouches!$M$2:$M$271,Bouches!$S$2:$S$271,A5,Bouches!$C$2:$C$271,"Soufflage") -> 90 | J5: =SUMIFS(Bouches!$M$2:$M$271,Bouches!$S$2:$S$271,A5,Bouches!$C$2:$C$271,"Reprise") -> 0 | K5: =SUMIFS(Bouches!$M$2:$M$271,Bouches!$S$2:$S$271,A5,Bouches!$C$2:$C$271,"Extraction") -> 0 | L5: 1 | M5: 1 | N5: =IF(AND(OR(G5<Hypothèses!$B$6,ABS(I5-G5)<=2),ABS(K5-H5)<=2),"oui","NON") -> oui | P5: B133
A6: L023 | B6: N00 | C6: HEB01 | D6: ch. couple | E6: CHAMBRE | F6: CTA 1-2 Héb. ouvert | G6: 90 | H6: 0 | I6: =SUMIFS(Bouches!$M$2:$M$271,Bouches!$S$2:$S$271,A6,Bouches!$C$2:$C$271,"Soufflage") -> 90 | J6: =SUMIFS(Bouches!$M$2:$M$271,Bouches!$S$2:$S$271,A6,Bouches!$C$2:$C$271,"Reprise") -> 0 | K6: =SUMIFS(Bouches!$M$2:$M$271,Bouches!$S$2:$S$271,A6,Bouches!$C$2:$C$271,"Extraction") -> 0 | L6: 1 | M6: 1 | N6: =IF(AND(OR(G6<Hypothèses!$B$6,ABS(I6-G6)<=2),ABS(K6-H6)<=2),"oui","NON") -> oui | P6: B181
A7: L024 | B7: N00 | C7: HEB01 | D7: ch. couple | E7: CHAMBRE | F7: CTA 1-2 Héb. ouvert | G7: 90 | H7: 0 | I7: =SUMIFS(Bouches!$M$2:$M$271,Bouches!$S$2:$S$271,A7,Bouches!$C$2:$C$271,"Soufflage") -> 90 | J7: =SUMIFS(Bouches!$M$2:$M$271,Bouches!$S$2:$S$271,A7,Bouches!$C$2:$C$271,"Reprise") -> 0 | K7: =SUMIFS(Bouches!$M$2:$M$271,Bouches!$S$2:$S$271,A7,Bouches!$C$2:$C$271,"Extraction") -> 0 | L7: 1 | M7: 1 | N7: =IF(AND(OR(G7<Hypothèses!$B$6,ABS(I7-G7)<=2),ABS(K7-H7)<=2),"oui","NON") -> oui | P7: B185
A8: L025 | B8: N00 | C8: HEB01 | D8: ch. couple | E8: CHAMBRE | F8: CTA 1-2 Héb. ouvert | G8: 90 | H8: 0 | I8: =SUMIFS(Bouches!$M$2:$M$271,Bouches!$S$2:$S$271,A8,Bouches!$C$2:$C$271,"Soufflage") -> 90 | J8: =SUMIFS(Bouches!$M$2:$M$271,Bouches!$S$2:$S$271,A8,Bouches!$C$2:$C$271,"Reprise") -> 0 | K8: =SUMIFS(Bouches!$M$2:$M$271,Bouches!$S$2:$S$271,A8,Bouches!$C$2:$C$271,"Extraction") -> 0 | L8: 1 | M8: 1 | N8: =IF(AND(OR(G8<Hypothèses!$B$6,ABS(I8-G8)<=2),ABS(K8-H8)<=2),"oui","NON") -> oui | P8: B066
A9: L026 | B9: N00 | C9: HEB01 | D9: ch. couple | E9: CHAMBRE | F9: CTA 1-2 Héb. ouvert | G9: 90 | H9: 0 | I9: =SUMIFS(Bouches!$M$2:$M$271,Bouches!$S$2:$S$271,A9,Bouches!$C$2:$C$271,"Soufflage") -> 90 | J9: =SUMIFS(Bouches!$M$2:$M$271,Bouches!$S$2:$S$271,A9,Bouches!$C$2:$C$271,"Reprise") -> 0 | K9: =SUMIFS(Bouches!$M$2:$M$271,Bouches!$S$2:$S$271,A9,Bouches!$C$2:$C$271,"Extraction") -> 0 | L9: 1 | M9: 1 | N9: =IF(AND(OR(G9<Hypothèses!$B$6,ABS(I9-G9)<=2),ABS(K9-H9)<=2),"oui","NON") -> oui | P9: B069
A10: L027 | B10: N00 | C10: HEB01 | D10: ch. couple | E10: CHAMBRE | F10: CTA 1-2 Héb. ouvert | G10: 90 | H10: 0 | I10: =SUMIFS(Bouches!$M$2:$M$271,Bouches!$S$2:$S$271,A10,Bouches!$C$2:$C$271,"Soufflage") -> 90 | J10: =SUMIFS(Bouches!$M$2:$M$271,Bouches!$S$2:$S$271,A10,Bouches!$C$2:$C$271,"Reprise") -> 0 | K10: =SUMIFS(Bouches!$M$2:$M$271,Bouches!$S$2:$S$271,A10,Bouches!$C$2:$C$271,"Extraction") -> 0 | L10: 1 | M10: 1 | N10: =IF(AND(OR(G10<Hypothèses!$B$6,ABS(I10-G10)<=2),ABS(K10-H10)<=2),"oui","NON") -> oui | P10: B095
A11: L028 | B11: N00 | C11: HEB01 | D11: ch. couple | E11: CHAMBRE | F11: CTA 1-2 Héb. ouvert | G11: 90 | H11: 0 | I11: =SUMIFS(Bouches!$M$2:$M$271,Bouches!$S$2:$S$271,A11,Bouches!$C$2:$C$271,"Soufflage") -> 90 | J11: =SUMIFS(Bouches!$M$2:$M$271,Bouches!$S$2:$S$271,A11,Bouches!$C$2:$C$271,"Reprise") -> 0 | K11: =SUMIFS(Bouches!$M$2:$M$271,Bouches!$S$2:$S$271,A11,Bouches!$C$2:$C$271,"Extraction") -> 0 | L11: 1 | M11: 1 | N11: =IF(AND(OR(G11<Hypothèses!$B$6,ABS(I11-G11)<=2),ABS(K11-H11)<=2),"oui","NON") -> oui | P11: B103
A12: L029 | B12: N00 | C12: HEB01 | D12: chambre | E12: CHAMBRE | F12: CTA 1-2 Héb. ouvert | G12: 90 | H12: 0 | I12: =SUMIFS(Bouches!$M$2:$M$271,Bouches!$S$2:$S$271,A12,Bouches!$C$2:$C$271,"Soufflage") -> 90 | J12: =SUMIFS(Bouches!$M$2:$M$271,Bouches!$S$2:$S$271,A12,Bouches!$C$2:$C$271,"Reprise") -> 0 | K12: =SUMIFS(Bouches!$M$2:$M$271,Bouches!$S$2:$S$271,A12,Bouches!$C$2:$C$271,"Extraction") -> 0 | L12: 1 | M12: 1 | N12: =IF(AND(OR(G12<Hypothèses!$B$6,ABS(I12-G12)<=2),ABS(K12-H12)<=2),"oui","NON") -> oui | P12: B124
A13: L030 | B13: N00 | C13: HEB01 | D13: chambre | E13: CHAMBRE | F13: CTA 1-2 Héb. ouvert | G13: 90 | H13: 0 | I13: =SUMIFS(Bouches!$M$2:$M$271,Bouches!$S$2:$S$271,A13,Bouches!$C$2:$C$271,"Soufflage") -> 90 | J13: =SUMIFS(Bouches!$M$2:$M$271,Bouches!$S$2:$S$271,A13,Bouches!$C$2:$C$271,"Reprise") -> 0 | K13: =SUMIFS(Bouches!$M$2:$M$271,Bouches!$S$2:$S$271,A13,Bouches!$C$2:$C$271,"Extraction") -> 0 | L13: 1 | M13: 1 | N13: =IF(AND(OR(G13<Hypothèses!$B$6,ABS(I13-G13)<=2),ABS(K13-H13)<=2),"oui","NON") -> oui | P13: B060
... A107: L240 | B107: N01 | C107: HEB01VV | D107: sdb | E107: SDB_CH | F107: CTA 1-2 Héb. ouvert | G107: 0 | H107: 90 | I107: =SUMIFS(Bouches!$M$2:$M$271,Bouches!$S$2:$S$271,A107,Bouches!$C$2:$C$271,"Soufflage") -> 0 | J107: =SUMIFS(Bouches!$M$2:$M$271,Bouches!$S$2:$S$271,A107,Bouches!$C$2:$C$271,"Reprise") -> 0 | K107: =SUMIFS(Bouches!$M$2:$M$271,Bouches!$S$2:$S$271,A107,Bouches!$C$2:$C$271,"Extraction") -> 90 | L107: 1 | M107: 1 | N107: =IF(AND(OR(G107<Hypothèses!$B$6,ABS(I107-G107)<=2),ABS(K107-H107)<=2),"oui","NON") -> oui | P107: B182
A108: L241 | B108: N01 | C108: HEB01WW | D108: sdb | E108: SDB_CH | F108: CTA 1-2 Héb. ouvert | G108: 0 | H108: 90 | I108: =SUMIFS(Bouches!$M$2:$M$271,Bouches!$S$2:$S$271,A108,Bouches!$C$2:$C$271,"Soufflage") -> 0 | J108: =SUMIFS(Bouches!$M$2:$M$271,Bouches!$S$2:$S$271,A108,Bouches!$C$2:$C$271,"Reprise") -> 0 | K108: =SUMIFS(Bouches!$M$2:$M$271,Bouches!$S$2:$S$271,A108,Bouches!$C$2:$C$271,"Extraction") -> 90 | L108: 1 | M108: 0 | N108: =IF(AND(OR(G108<Hypothèses!$B$6,ABS(I108-G108)<=2),ABS(K108-H108)<=2),"oui","NON") -> oui | O108: 1 bouche(s) à raccorder | P108: B369
A109: L242 | B109: N01 | C109: HEB01XX | D109: sdb | E109: SDB_CH | F109: CTA 1-2 Héb. ouvert | G109: 0 | H109: 90 | I109: =SUMIFS(Bouches!$M$2:$M$271,Bouches!$S$2:$S$271,A109,Bouches!$C$2:$C$271,"Soufflage") -> 0 | J109: =SUMIFS(Bouches!$M$2:$M$271,Bouches!$S$2:$S$271,A109,Bouches!$C$2:$C$271,"Reprise") -> 0 | K109: =SUMIFS(Bouches!$M$2:$M$271,Bouches!$S$2:$S$271,A109,Bouches!$C$2:$C$271,"Extraction") -> 90 | L109: 1 | M109: 1 | N109: =IF(AND(OR(G109<Hypothèses!$B$6,ABS(I109-G109)<=2),ABS(K109-H109)<=2),"oui","NON") -> oui | P109: B043
A110: L243 | B110: N01 | C110: HEB01YY | D110: sdb | E110: SDB_CH | F110: CTA 1-2 Héb. ouvert | G110: 0 | H110: 90 | I110: =SUMIFS(Bouches!$M$2:$M$271,Bouches!$S$2:$S$271,A110,Bouches!$C$2:$C$271,"Soufflage") -> 0 | J110: =SUMIFS(Bouches!$M$2:$M$271,Bouches!$S$2:$S$271,A110,Bouches!$C$2:$C$271,"Reprise") -> 0 | K110: =SUMIFS(Bouches!$M$2:$M$271,Bouches!$S$2:$S$271,A110,Bouches!$C$2:$C$271,"Extraction") -> 90 | L110: 1 | M110: 1 | N110: =IF(AND(OR(G110<Hypothèses!$B$6,ABS(I110-G110)<=2),ABS(K110-H110)<=2),"oui","NON") -> oui | P110: B169
A111: L244 | B111: N01 | C111: HEB01ZZ | D111: sdb | E111: SDB_CH | F111: CTA 1-2 Héb. ouvert | G111: 0 | H111: 90 | I111: =SUMIFS(Bouches!$M$2:$M$271,Bouches!$S$2:$S$271,A111,Bouches!$C$2:$C$271,"Soufflage") -> 0 | J111: =SUMIFS(Bouches!$M$2:$M$271,Bouches!$S$2:$S$271,A111,Bouches!$C$2:$C$271,"Reprise") -> 0 | K111: =SUMIFS(Bouches!$M$2:$M$271,Bouches!$S$2:$S$271,A111,Bouches!$C$2:$C$271,"Extraction") -> 90 | L111: 1 | M111: 1 | N111: =IF(AND(OR(G111<Hypothèses!$B$6,ABS(I111-G111)<=2),ABS(K111-H111)<=2),"oui","NON") -> oui | P111: B097
A112: L114 | B112: N01 | C112: HEB01 | D112: chambre | E112: CHAMBRE | F112: CTA 3-4 Héb. fermé | G112: 90 | H112: 0 | I112: =SUMIFS(Bouches!$M$2:$M$271,Bouches!$S$2:$S$271,A112,Bouches!$C$2:$C$271,"Soufflage") -> 90 | J112: =SUMIFS(Bouches!$M$2:$M$271,Bouches!$S$2:$S$271,A112,Bouches!$C$2:$C$271,"Reprise") -> 0 | K112: =SUMIFS(Bouches!$M$2:$M$271,Bouches!$S$2:$S$271,A112,Bouches!$C$2:$C$271,"Extraction") -> 0 | L112: 1 | M112: 1 | N112: =IF(AND(OR(G112<Hypothèses!$B$6,ABS(I112-G112)<=2),ABS(K112-H112)<=2),"oui","NON") -> oui | P112: B346
A113: L115 | B113: N01 | C113: HEB01 | D113: chambre | E113: CHAMBRE | F113: CTA 3-4 Héb. fermé | G113: 90 | H113: 0 | I113: =SUMIFS(Bouches!$M$2:$M$271,Bouches!$S$2:$S$271,A113,Bouches!$C$2:$C$271,"Soufflage") -> 90 | J113: =SUMIFS(Bouches!$M$2:$M$271,Bouches!$S$2:$S$271,A113,Bouches!$C$2:$C$271,"Reprise") -> 0 | K113: =SUMIFS(Bouches!$M$2:$M$271,Bouches!$S$2:$S$271,A113,Bouches!$C$2:$C$271,"Extraction") -> 0 | L113: 1 | M113: 1 | N113: =IF(AND(OR(G113<Hypothèses!$B$6,ABS(I113-G113)<=2),ABS(K113-H113)<=2),"oui","NON") -> oui | P113: B365
A114: L116 | B114: N01 | C114: HEB01 | D114: chambre | E114: CHAMBRE | F114: CTA 3-4 Héb. fermé | G114: 90 | H114: 0 | I114: =SUMIFS(Bouches!$M$2:$M$271,Bouches!$S$2:$S$271,A114,Bouches!$C$2:$C$271,"Soufflage") -> 90 | J114: =SUMIFS(Bouches!$M$2:$M$271,Bouches!$S$2:$S$271,A114,Bouches!$C$2:$C$271,"Reprise") -> 0 | K114: =SUMIFS(Bouches!$M$2:$M$271,Bouches!$S$2:$S$271,A114,Bouches!$C$2:$C$271,"Extraction") -> 0 | L114: 1 | M114: 1 | N114: =IF(AND(OR(G114<Hypothèses!$B$6,ABS(I114-G114)<=2),ABS(K114-H114)<=2),"oui","NON") -> oui | P114: B347
A115: L117 | B115: N01 | C115: HEB01 | D115: chambre | E115: CHAMBRE | F115: CTA 3-4 Héb. fermé | G115: 90 | H115: 0 | I115: =SUMIFS(Bouches!$M$2:$M$271,Bouches!$S$2:$S$271,A115,Bouches!$C$2:$C$271,"Soufflage") -> 90 | J115: =SUMIFS(Bouches!$M$2:$M$271,Bouches!$S$2:$S$271,A115,Bouches!$C$2:$C$271,"Reprise") -> 0 | K115: =SUMIFS(Bouches!$M$2:$M$271,Bouches!$S$2:$S$271,A115,Bouches!$C$2:$C$271,"Extraction") -> 0 | L115: 1 | M115: 1 | N115: =IF(AND(OR(G115<Hypothèses!$B$6,ABS(I115-G115)<=2),ABS(K115-H115)<=2),"oui","NON") -> oui | P115: B100
A116: L118 | B116: N01 | C116: HEB01 | D116: chambre | E116: CHAMBRE | F116: CTA 3-4 Héb. fermé | G116: 90 | H116: 0 | I116: =SUMIFS(Bouches!$M$2:$M$271,Bouches!$S$2:$S$271,A116,Bouches!$C$2:$C$271,"Soufflage") -> 90 | J116: =SUMIFS(Bouches!$M$2:$M$271,Bouches!$S$2:$S$271,A116,Bouches!$C$2:$C$271,"Reprise") -> 0 | K116: =SUMIFS(Bouches!$M$2:$M$271,Bouches!$S$2:$S$271,A116,Bouches!$C$2:$C$271,"Extraction") -> 0 | L116: 1 | M116: 1 | N116: =IF(AND(OR(G116<Hypothèses!$B$6,ABS(I116-G116)<=2),ABS(K116-H116)<=2),"oui","NON") -> oui | P116: B375
A117: L119 | B117: N01 | C117: HEB01 | D117: chambre | E117: CHAMBRE | F117: CTA 3-4 Héb. fermé | G117: 90 | H117: 0 | I117: =SUMIFS(Bouches!$M$2:$M$271,Bouches!$S$2:$S$271,A117,Bouches!$C$2:$C$271,"Soufflage") -> 90 | J117: =SUMIFS(Bouches!$M$2:$M$271,Bouches!$S$2:$S$271,A117,Bouches!$C$2:$C$271,"Reprise") -> 0 | K117: =SUMIFS(Bouches!$M$2:$M$271,Bouches!$S$2:$S$271,A117,Bouches!$C$2:$C$271,"Extraction") -> 0 | L117: 1 | M117: 1 | N117: =IF(AND(OR(G117<Hypothèses!$B$6,ABS(I117-G117)<=2),ABS(K117-H117)<=2),"oui","NON") -> oui | P117: B368
A118: L120 | B118: N01 | C118: HEB01 | D118: chambre | E118: CHAMBRE | F118: CTA 3-4 Héb. fermé | G118: 90 | H118: 0 | I118: =SUMIFS(Bouches!$M$2:$M$271,Bouches!$S$2:$S$271,A118,Bouches!$C$2:$C$271,"Soufflage") -> 90 | J118: =SUMIFS(Bouches!$M$2:$M$271,Bouches!$S$2:$S$271,A118,Bouches!$C$2:$C$271,"Reprise") -> 0 | K118: =SUMIFS(Bouches!$M$2:$M$271,Bouches!$S$2:$S$271,A118,Bouches!$C$2:$C$271,"Extraction") -> 0 | L118: 1 | M118: 1 | N118: =IF(AND(OR(G118<Hypothèses!$B$6,ABS(I118-G118)<=2),ABS(K118-H118)<=2),"oui","NON") -> oui | P118: B332
A119: L121 | B119: N01 | C119: HEB01 | D119: chambre | E119: CHAMBRE | F119: CTA 3-4 Héb. fermé | G119: 90 | H119: 0 | I119: =SUMIFS(Bouches!$M$2:$M$271,Bouches!$S$2:$S$271,A119,Bouches!$C$2:$C$271,"Soufflage") -> 90 | J119: =SUMIFS(Bouches!$M$2:$M$271,Bouches!$S$2:$S$271,A119,Bouches!$C$2:$C$271,"Reprise") -> 0 | K119: =SUMIFS(Bouches!$M$2:$M$271,Bouches!$S$2:$S$271,A119,Bouches!$C$2:$C$271,"Extraction") -> 0 | L119: 1 | M119: 1 | N119: =IF(AND(OR(G119<Hypothèses!$B$6,ABS(I119-G119)<=2),ABS(K119-H119)<=2),"oui","NON") -> oui | P119: B348
A120: L122 | B120: N01 | C120: HEB01 | D120: chambre | E120: CHAMBRE | F120: CTA 3-4 Héb. fermé | G120: 90 | H120: 0 | I120: =SUMIFS(Bouches!$M$2:$M$271,Bouches!$S$2:$S$271,A120,Bouches!$C$2:$C$271,"Soufflage") -> 90 | J120: =SUMIFS(Bouches!$M$2:$M$271,Bouches!$S$2:$S$271,A120,Bouches!$C$2:$C$271,"Reprise") -> 0 | K120: =SUMIFS(Bouches!$M$2:$M$271,Bouches!$S$2:$S$271,A120,Bouches!$C$2:$C$271,"Extraction") -> 0 | L120: 1 | M120: 1 | N120: =IF(AND(OR(G120<Hypothèses!$B$6,ABS(I120-G120)<=2),ABS(K120-H120)<=2),"oui","NON") -> oui | P120: B376
... A135: L137 | B135: N01 | C135: HEB01 | D135: chambre | E135: CHAMBRE | F135: CTA 3-4 Héb. fermé | G135: 90 | H135: 0 | I135: =SUMIFS(Bouches!$M$2:$M$271,Bouches!$S$2:$S$271,A135,Bouches!$C$2:$C$271,"Soufflage") -> 90 | J135: =SUMIFS(Bouches!$M$2:$M$271,Bouches!$S$2:$S$271,A135,Bouches!$C$2:$C$271,"Reprise") -> 0 | K135: =SUMIFS(Bouches!$M$2:$M$271,Bouches!$S$2:$S$271,A135,Bouches!$C$2:$C$271,"Extraction") -> 0 | L135: 1 | M135: 1 | N135: =IF(AND(OR(G135<Hypothèses!$B$6,ABS(I135-G135)<=2),ABS(K135-H135)<=2),"oui","NON") -> oui | P135: B351
A136: L138 | B136: N01 | C136: HEB01 | D136: chambre | E136: CHAMBRE | F136: CTA 3-4 Héb. fermé | G136: 90 | H136: 0 | I136: =SUMIFS(Bouches!$M$2:$M$271,Bouches!$S$2:$S$271,A136,Bouches!$C$2:$C$271,"Soufflage") -> 90 | J136: =SUMIFS(Bouches!$M$2:$M$271,Bouches!$S$2:$S$271,A136,Bouches!$C$2:$C$271,"Reprise") -> 0 | K136: =SUMIFS(Bouches!$M$2:$M$271,Bouches!$S$2:$S$271,A136,Bouches!$C$2:$C$271,"Extraction") -> 0 | L136: 1 | M136: 0 | N136: =IF(AND(OR(G136<Hypothèses!$B$6,ABS(I136-G136)<=2),ABS(K136-H136)<=2),"oui","NON") -> oui | O136: 1 bouche(s) à raccorder | P136: B398
A137: L139 | B137: N01 | C137: HEB01 | D137: chambre | E137: CHAMBRE | F137: CTA 3-4 Héb. fermé | G137: 90 | H137: 0 | I137: =SUMIFS(Bouches!$M$2:$M$271,Bouches!$S$2:$S$271,A137,Bouches!$C$2:$C$271,"Soufflage") -> 90 | J137: =SUMIFS(Bouches!$M$2:$M$271,Bouches!$S$2:$S$271,A137,Bouches!$C$2:$C$271,"Reprise") -> 0 | K137: =SUMIFS(Bouches!$M$2:$M$271,Bouches!$S$2:$S$271,A137,Bouches!$C$2:$C$271,"Extraction") -> 0 | L137: 1 | M137: 1 | N137: =IF(AND(OR(G137<Hypothèses!$B$6,ABS(I137-G137)<=2),ABS(K137-H137)<=2),"oui","NON") -> oui | P137: B343
A138: L153 | B138: N01 | C138: HEB01AAAA | D138: sdb | E138: SDB_CH | F138: CTA 3-4 Héb. fermé | G138: 0 | H138: 90 | I138: =SUMIFS(Bouches!$M$2:$M$271,Bouches!$S$2:$S$271,A138,Bouches!$C$2:$C$271,"Soufflage") -> 0 | J138: =SUMIFS(Bouches!$M$2:$M$271,Bouches!$S$2:$S$271,A138,Bouches!$C$2:$C$271,"Reprise") -> 0 | K138: =SUMIFS(Bouches!$M$2:$M$271,Bouches!$S$2:$S$271,A138,Bouches!$C$2:$C$271,"Extraction") -> 90 | L138: 1 | M138: 1 | N138: =IF(AND(OR(G138<Hypothèses!$B$6,ABS(I138-G138)<=2),ABS(K138-H138)<=2),"oui","NON") -> oui | P138: B118
A139: L154 | B139: N01 | C139: HEB01BBBB | D139: sdb | E139: SDB_CH | F139: CTA 3-4 Héb. fermé | G139: 0 | H139: 90 | I139: =SUMIFS(Bouches!$M$2:$M$271,Bouches!$S$2:$S$271,A139,Bouches!$C$2:$C$271,"Soufflage") -> 0 | J139: =SUMIFS(Bouches!$M$2:$M$271,Bouches!$S$2:$S$271,A139,Bouches!$C$2:$C$271,"Reprise") -> 0 | K139: =SUMIFS(Bouches!$M$2:$M$271,Bouches!$S$2:$S$271,A139,Bouches!$C$2:$C$271,"Extraction") -> 90 | L139: 1 | M139: 1 | N139: =IF(AND(OR(G139<Hypothèses!$B$6,ABS(I139-G139)<=2),ABS(K139-H139)<=2),"oui","NON") -> oui | P139: B374
A140: L155 | B140: N01 | C140: HEB01CCCC | D140: sdb | E140: SDB_CH | F140: CTA 3-4 Héb. fermé | G140: 0 | H140: 90 | I140: =SUMIFS(Bouches!$M$2:$M$271,Bouches!$S$2:$S$271,A140,Bouches!$C$2:$C$271,"Soufflage") -> 0 | J140: =SUMIFS(Bouches!$M$2:$M$271,Bouches!$S$2:$S$271,A140,Bouches!$C$2:$C$271,"Reprise") -> 0 | K140: =SUMIFS(Bouches!$M$2:$M$271,Bouches!$S$2:$S$271,A140,Bouches!$C$2:$C$271,"Extraction") -> 90 | L140: 1 | M140: 1 | N140: =IF(AND(OR(G140<Hypothèses!$B$6,ABS(I140-G140)<=2),ABS(K140-H140)<=2),"oui","NON") -> oui | P140: B356
A141: L156 | B141: N01 | C141: HEB01DDDD | D141: sdb | E141: SDB_CH | F141: CTA 3-4 Héb. fermé | G141: 0 | H141: 90 | I141: =SUMIFS(Bouches!$M$2:$M$271,Bouches!$S$2:$S$271,A141,Bouches!$C$2:$C$271,"Soufflage") -> 0 | J141: =SUMIFS(Bouches!$M$2:$M$271,Bouches!$S$2:$S$271,A141,Bouches!$C$2:$C$271,"Reprise") -> 0 | K141: =SUMIFS(Bouches!$M$2:$M$271,Bouches!$S$2:$S$271,A141,Bouches!$C$2:$C$271,"Extraction") -> 90 | L141: 1 | M141: 1 | N141: =IF(AND(OR(G141<Hypothèses!$B$6,ABS(I141-G141)<=2),ABS(K141-H141)<=2),"oui","NON") -> oui | P141: B317
A142: L157 | B142: N01 | C142: HEB01EEE | D142: sdb | E142: SDB_CH | F142: CTA 3-4 Héb. fermé | G142: 0 | H142: 90 | I142: =SUMIFS(Bouches!$M$2:$M$271,Bouches!$S$2:$S$271,A142,Bouches!$C$2:$C$271,"Soufflage") -> 0 | J142: =SUMIFS(Bouches!$M$2:$M$271,Bouches!$S$2:$S$271,A142,Bouches!$C$2:$C$271,"Reprise") -> 0 | K142: =SUMIFS(Bouches!$M$2:$M$271,Bouches!$S$2:$S$271,A142,Bouches!$C$2:$C$271,"Extraction") -> 90 | L142: 1 | M142: 1 | N142: =IF(AND(OR(G142<Hypothèses!$B$6,ABS(I142-G142)<=2),ABS(K142-H142)<=2),"oui","NON") -> oui | P142: B321
A143: L158 | B143: N01 | C143: HEB01FFF | D143: sdb | E143: SDB_CH | F143: CTA 3-4 Héb. fermé | G143: 0 | H143: 90 | I143: =SUMIFS(Bouches!$M$2:$M$271,Bouches!$S$2:$S$271,A143,Bouches!$C$2:$C$271,"Soufflage") -> 0 | J143: =SUMIFS(Bouches!$M$2:$M$271,Bouches!$S$2:$S$271,A143,Bouches!$C$2:$C$271,"Reprise") -> 0 | K143: =SUMIFS(Bouches!$M$2:$M$271,Bouches!$S$2:$S$271,A143,Bouches!$C$2:$C$271,"Extraction") -> 90 | L143: 1 | M143: 1 | N143: =IF(AND(OR(G143<Hypothèses!$B$6,ABS(I143-G143)<=2),ABS(K143-H143)<=2),"oui","NON") -> oui | P143: B318
A144: L159 | B144: N01 | C144: HEB01GGG | D144: sdb | E144: SDB_CH | F144: CTA 3-4 Héb. fermé | G144: 0 | H144: 90 | I144: =SUMIFS(Bouches!$M$2:$M$271,Bouches!$S$2:$S$271,A144,Bouches!$C$2:$C$271,"Soufflage") -> 0 | J144: =SUMIFS(Bouches!$M$2:$M$271,Bouches!$S$2:$S$271,A144,Bouches!$C$2:$C$271,"Reprise") -> 0 | K144: =SUMIFS(Bouches!$M$2:$M$271,Bouches!$S$2:$S$271,A144,Bouches!$C$2:$C$271,"Extraction") -> 90 | L144: 1 | M144: 1 | N144: =IF(AND(OR(G144<Hypothèses!$B$6,ABS(I144-G144)<=2),ABS(K144-H144)<=2),"oui","NON") -> oui | P144: B018
A145: L160 | B145: N01 | C145: HEB01HHH | D145: sdb | E145: SDB_CH | F145: CTA 3-4 Héb. fermé | G145: 0 | H145: 90 | I145: =SUMIFS(Bouches!$M$2:$M$271,Bouches!$S$2:$S$271,A145,Bouches!$C$2:$C$271,"Soufflage") -> 0 | J145: =SUMIFS(Bouches!$M$2:$M$271,Bouches!$S$2:$S$271,A145,Bouches!$C$2:$C$271,"Reprise") -> 0 | K145: =SUMIFS(Bouches!$M$2:$M$271,Bouches!$S$2:$S$271,A145,Bouches!$C$2:$C$271,"Extraction") -> 90 | L145: 1 | M145: 1 | N145: =IF(AND(OR(G145<Hypothèses!$B$6,ABS(I145-G145)<=2),ABS(K145-H145)<=2),"oui","NON") -> oui | P145: B354
A146: L161 | B146: N01 | C146: HEB01III | D146: sdb | E146: SDB_CH | F146: CTA 3-4 Héb. fermé | G146: 0 | H146: 90 | I146: =SUMIFS(Bouches!$M$2:$M$271,Bouches!$S$2:$S$271,A146,Bouches!$C$2:$C$271,"Soufflage") -> 0 | J146: =SUMIFS(Bouches!$M$2:$M$271,Bouches!$S$2:$S$271,A146,Bouches!$C$2:$C$271,"Reprise") -> 0 | K146: =SUMIFS(Bouches!$M$2:$M$271,Bouches!$S$2:$S$271,A146,Bouches!$C$2:$C$271,"Extraction") -> 90 | L146: 1 | M146: 1 | N146: =IF(AND(OR(G146<Hypothèses!$B$6,ABS(I146-G146)<=2),ABS(K146-H146)<=2),"oui","NON") -> oui | P146: B331
A147: L162 | B147: N01 | C147: HEB01JJJ | D147: sdb | E147: SDB_CH | F147: CTA 3-4 Héb. fermé | G147: 0 | H147: 90 | I147: =SUMIFS(Bouches!$M$2:$M$271,Bouches!$S$2:$S$271,A147,Bouches!$C$2:$C$271,"Soufflage") -> 0 | J147: =SUMIFS(Bouches!$M$2:$M$271,Bouches!$S$2:$S$271,A147,Bouches!$C$2:$C$271,"Reprise") -> 0 | K147: =SUMIFS(Bouches!$M$2:$M$271,Bouches!$S$2:$S$271,A147,Bouches!$C$2:$C$271,"Extraction") -> 90 | L147: 1 | M147: 1 | N147: =IF(AND(OR(G147<Hypothèses!$B$6,ABS(I147-G147)<=2),ABS(K147-H147)<=2),"oui","NON") -> oui | P147: B370
...

Sheet Écarts au CCTP
A1: Sujet | B1: Ce que dit le dossier (DCE) | C1: Ce qu'on a fait dans la maquette | D1: Pourquoi / suite
A2: Raccordement des bouches | B2: CCTP 4.10.6 / 4.11.7 : bouches raccordées par flexible phonique M0, 50 cm maxi | C2: Antennes en gaine rigide jusqu'à la bouche (piquage + coudes à angle carré) | D2: Choix de l'équipe (pas de flexible dans la maquette). Le flexible de 50 cm pourra être ajouté au DOE / à l'exécution.
A3: Régulateurs de débit constant | B3: CCTP 4.10.5 / 4.11.5 : un régulateur Rad Régul'air ou RDC-RM à chaque bouche de soufflage | C3: Non modélisés (accessoire dans la gaine) | D3: À ajouter si on modélise les accessoires (famille d'accessoire de gaine).
A4: Bouches d'extraction des salles de bains | B4: CCTP 4.10.6 : à la charge du lot cabine préfabriquée | C4: Modélisées (81 bouches 90 m³/h) pour le calcul et la synthèse | D4: Fournies par le lot cabine, raccordées par nous.
A5: Débit CTA 5 | B5: CCTP 4.11.2 : 8 800 m³/h | C5: Bouches dimensionnées sur nos débits réglementaires : 6 123 m³/h au soufflage | D5: À trancher avec le prof : garder 8 800 m³/h (bouches et gaines × 1,4 environ) ou nos minimums.
A6: Débit CTA 2 | B6: CCTP 4.10.2 : 2 330 m³/h | C6: 2 430 m³/h (27 chambres × 90 : une chambre de plus dans la maquette) | D6: Écart de 4 %, à signaler.
A7: Petits stocks (< 25 m³/h) | B7: Débits par local : 0,36 m³/h/m² (95 m³/h au total pour 22 locaux) | C7: Pas de bouche : transfert d'air par la porte | D7: Choix d'Allan.
A8: VMC simple flux sanitaires | B8: CCTP 4.12 : caisson d'extraction C4 en toiture, gaines, bouches autoréglables | C8: 6 caissons C4 en toiture (VMC 1 à 6), montées, collecteurs et antennes rigides : les 46 bouches (3 090 m³/h) sont raccordées | D8: Rejets à plus de 8 m des prises d'air neuf des CTA (vérifié). Caissons VMC 2 et VMC 4 : posés en rive, à caler avec l'acrotère.
A9: Compensation des sanitaires | B9: CCTP 4.12.6 : détalonnage < 120 m³/h, bouches de transfert au-delà | C9: Offices et tisanerie (450 m³/h chacun) : bouches de transfert (grilles en porte ou en cloison) ; locaux < 120 m³/h : détalonnage des portes | D9: Grilles de transfert à commander avec les menuiseries ; pas dessinées dans la maquette CVC.

Sheet Hypothèses
A1: Hypothèses
A3: Vitesse maxi au col des bouches (m/s) | B3: 2.5 | C3: Hypothèse équipe : vitesse basse pour limiter le bruit (CCTP § 4.10.4)
A4: Hauteur du col / des antennes (mm) | B4: 60 | C4: Hypothèse équipe : antennes plates pour passer au-dessus des gaines principales
A5: Débit maxi par bouche CTA (m³/h) | B5: 400 | C5: Hypothèse équipe
A6: Débit mini pour poser une bouche (m³/h) | B6: 25 | C6: Choix d'Allan : en dessous, transfert d'air par la porte
A7: Débit maxi par bouche VMC (m³/h) | B7: 150 | C7: Hypothèse équipe (bouche autoréglable)
