Workbook

Sheet Synthèse
A1: Gaines principales de ventilation – synthèse par CTA
A2: EHPAD La Bassée · lot 12 CVC · méthode du CCTP § 2.2.5 (vitesse maxi selon le débit). Détail dans l'onglet « Tronçons ».
A4: CTA | B4: Réseau | C4: Débit CCTP (m³/h) | D4: Débit calculé (m³/h) | E4: Écart | F4: Gaine au départ (L × H mm) | G4: Vitesse au départ (m/s) | H4: Nombre de tronçons | I4: Longueur totale (m) | J4: Pertes circuit défavorisé (Pa) | K4: Tronçons trop rapides | L4: Tronçons trop hauts pour le plénum | M4: Descente / gaine technique
A5: CTA 1 | B5: CTA 1 – zone ouverte aile Nord | C5: 2520 | D5: =Tronçons!H5 | E5: =IF(C5>0,D5/C5-1,"") | F5: =Tronçons!L5&" × "&Tronçons!K5 | G5: =Tronçons!N5 | H5: =COUNTIF(Tronçons!$A$5:$A$279,A5) | I5: =SUMIF(Tronçons!$A$5:$A$279,A5,Tronçons!$G$5:$G$279) | J5: =MAX(SUMIFS(Tronçons!$T$5:$T$279,Tronçons!$A$5:$A$279,A5,Tronçons!$U$5:$U$279,"X",Tronçons!$E$5:$E$279,"Soufflage"),SUMIFS(Tronçons!$T$5:$T$279,Tronçons!$A$5:$A$279,A5,Tronçons!$U$5:$U$279,"X",Tronçons!$E$5:$E$279,"Reprise")) | K5: =COUNTIFS(Tronçons!$A$5:$A$279,A5,Tronçons!$O$5:$O$279,"NON") | L5: =COUNTIFS(Tronçons!$A$5:$A$279,A5,Tronçons!$V$5:$V$279,"NON") | M5: gaine technique dans le local ménage (RDC + étage)
A6: CTA 2 | B6: CTA 2 – zone ouverte aile Sud | C6: 2330 | D6: =Tronçons!H75 | E6: =IF(C6>0,D6/C6-1,"") | F6: =Tronçons!L75&" × "&Tronçons!K75 | G6: =Tronçons!N75 | H6: =COUNTIF(Tronçons!$A$5:$A$279,A6) | I6: =SUMIF(Tronçons!$A$5:$A$279,A6,Tronçons!$G$5:$G$279) | J6: =MAX(SUMIFS(Tronçons!$T$5:$T$279,Tronçons!$A$5:$A$279,A6,Tronçons!$U$5:$U$279,"X",Tronçons!$E$5:$E$279,"Soufflage"),SUMIFS(Tronçons!$T$5:$T$279,Tronçons!$A$5:$A$279,A6,Tronçons!$U$5:$U$279,"X",Tronçons!$E$5:$E$279,"Reprise")) | K6: =COUNTIFS(Tronçons!$A$5:$A$279,A6,Tronçons!$O$5:$O$279,"NON") | L6: =COUNTIFS(Tronçons!$A$5:$A$279,A6,Tronçons!$V$5:$V$279,"NON") | M6: gaine technique dans l'office (RDC + étage)
A7: CTA 3 | B7: CTA 3 – zone fermée aile Nord | C7: 1170 | D7: =Tronçons!H139 | E7: =IF(C7>0,D7/C7-1,"") | F7: =Tronçons!L139&" × "&Tronçons!K139 | G7: =Tronçons!N139 | H7: =COUNTIF(Tronçons!$A$5:$A$279,A7) | I7: =SUMIF(Tronçons!$A$5:$A$279,A7,Tronçons!$G$5:$G$279) | J7: =MAX(SUMIFS(Tronçons!$T$5:$T$279,Tronçons!$A$5:$A$279,A7,Tronçons!$U$5:$U$279,"X",Tronçons!$E$5:$E$279,"Soufflage"),SUMIFS(Tronçons!$T$5:$T$279,Tronçons!$A$5:$A$279,A7,Tronçons!$U$5:$U$279,"X",Tronçons!$E$5:$E$279,"Reprise")) | K7: =COUNTIFS(Tronçons!$A$5:$A$279,A7,Tronçons!$O$5:$O$279,"NON") | L7: =COUNTIFS(Tronçons!$A$5:$A$279,A7,Tronçons!$V$5:$V$279,"NON") | M7: descente directe par la toiture dans le couloir, au centre (étage seul) : la toiture de l'aile est prise par les tuiles et les PV
A8: CTA 4 | B8: CTA 4 – zone fermée aile Sud | C8: 1170 | D8: =Tronçons!H169 | E8: =IF(C8>0,D8/C8-1,"") | F8: =Tronçons!L169&" × "&Tronçons!K169 | G8: =Tronçons!N169 | H8: =COUNTIF(Tronçons!$A$5:$A$279,A8) | I8: =SUMIF(Tronçons!$A$5:$A$279,A8,Tronçons!$G$5:$G$279) | J8: =MAX(SUMIFS(Tronçons!$T$5:$T$279,Tronçons!$A$5:$A$279,A8,Tronçons!$U$5:$U$279,"X",Tronçons!$E$5:$E$279,"Soufflage"),SUMIFS(Tronçons!$T$5:$T$279,Tronçons!$A$5:$A$279,A8,Tronçons!$U$5:$U$279,"X",Tronçons!$E$5:$E$279,"Reprise")) | K8: =COUNTIFS(Tronçons!$A$5:$A$279,A8,Tronçons!$O$5:$O$279,"NON") | L8: =COUNTIFS(Tronçons!$A$5:$A$279,A8,Tronçons!$V$5:$V$279,"NON") | M8: descente directe par la toiture dans le couloir (étage seul)
A9: CTA 5 | B9: CTA 5 – locaux communs | C9: 8800 | D9: =Tronçons!H199 | E9: =IF(C9>0,D9/C9-1,"") | F9: =Tronçons!L199&" × "&Tronçons!K199 | G9: =Tronçons!N199 | H9: =COUNTIF(Tronçons!$A$5:$A$279,A9) | I9: =SUMIF(Tronçons!$A$5:$A$279,A9,Tronçons!$G$5:$G$279) | J9: =MAX(SUMIFS(Tronçons!$T$5:$T$279,Tronçons!$A$5:$A$279,A9,Tronçons!$U$5:$U$279,"X",Tronçons!$E$5:$E$279,"Soufflage"),SUMIFS(Tronçons!$T$5:$T$279,Tronçons!$A$5:$A$279,A9,Tronçons!$U$5:$U$279,"X",Tronçons!$E$5:$E$279,"Reprise")) | K9: =COUNTIFS(Tronçons!$A$5:$A$279,A9,Tronçons!$O$5:$O$279,"NON") | L9: =COUNTIFS(Tronçons!$A$5:$A$279,A9,Tronçons!$V$5:$V$279,"NON") | M9: CTA sur la terrasse libre à l'ouest, gaines en toiture à 90° jusqu'à la gaine technique du local ménage (RDC) ; étage alimenté depuis le RDC par le local linge S
A11: À retenir
A12: • CTA 1, 3 et 4 : notre débit (90 m³/h × chambres) tombe exactement sur celui du CCTP. CTA 2 : une chambre de plus (+4 %).
A13: • CTA 5 : nos minimums réglementaires donnent moins que les 8 800 m³/h du CCTP ; le réseau est dimensionné sur nos débits, à reprendre si on garde 8 800 m³/h (sections × 1,4 environ).
A14: • Toutes les gaines respectent la vitesse maxi du CCTP et passent sous les poutres 20x40 (hauteur 300 mm maxi ; 350 mm pour le tronc RDC de la CTA 5, posé plus haut). Dessous des gaines au-dessus du faux plafond partout.
A15: • Pertes du circuit défavorisé = réseau seul (sans filtres, batterie, bouches), à ajouter pour choisir la pression des ventilateurs des CTA.
A16: • Tracé v2 (17/10) : CTA déplacées au-dessus de leur descente, plus de gaine sur les panneaux PV ni hors du bâtiment, angles à 90°. Gaines techniques à valider avec l'architecte.
A17: • Dans Revit, la section est gardée à travers les coudes et les tés (réduction après le raccord) : quelques morceaux sont un peu plus grands que le calcul.

Sheet Hypothèses
A1: Hypothèses de dimensionnement des gaines
A2: Les cellules en bleu sont des données : on peut les modifier, tout le classeur se recalcule.
A4: Vitesse maximale selon le débit (CCTP lot 12 § 2.2.5)
A5: Débit à partir de (m³/h) | B5: Débit jusqu'à (m³/h) | C5: Vitesse maxi (m/s)
A6: 0 | B6: 300 | C6: 3
A7: 300.001 | B7: 550 | C7: 3.5
A8: 550.001 | B8: 800 | C8: 4
A9: 800.001 | B9: 1500 | C9: 4.5
A10: 1500.001 | B10: 2000 | C10: 5
A11: 2000.001 | B11: 4000 | C11: 5.5
A12: 4000.001 | B12: 6000 | C12: 6
A13: 6000.001 | B13: 12000 | C13: 6.5
A14: 12000.001 | B14: 18500 | C14: 7
A15: 18500.001 | B15: 25000 | C15: 7.5
A16: 25000.001 | B16: 999999 | C16: 10
A17: Source : CCTP lot 12 § 2.2.5 « Calcul des conduits aérauliques » ; § 4.10.4 : « vitesse d'air basse […] ne devront pas provoquer de bruit d'écoulement ».
A19: Masse volumique de l'air ρ (kg/m³) | B19: 1.2 | C19: Air à 20 °C
A20: Viscosité cinématique ν (m²/s) | B20: 1.5e-05 | C20: Air à 20 °C
A21: Rugosité de la tôle galvanisée ε (m) | B21: 0.00015 | C21: Valeur courante pour l'acier galvanisé
A22: Majoration pour pertes singulières (%) | B22: 0.5 | C22: Hypothèse équipe : coudes, tés et réductions = 50 % des pertes linéaires
A23: Hauteur de gaine jusqu'à 2 000 m³/h (mm) | B23: 250 | C23: Hypothèse équipe : gaines rectangulaires plates dans le plénum
A24: Hauteur de gaine au-delà de 2 000 m³/h (mm) | B24: 300 | C24: Hypothèse équipe : 300 mm maxi pour passer sous les poutres 20x40 (dessus de gaine à 2,93 / 6,29 m)
A25: Hauteur des gaines de la CTA 4 (mm) | B25: 300 | C25: Hypothèse équipe : gaines plus étroites pour tenir à deux dans le couloir de l'unité fermée Sud
A26: Largeur minimale (mm) | B26: 200 | C26: Hypothèse équipe
A27: Pas des largeurs (mm) | B27: 50 | C27: Dimensions commerciales par pas de 50 mm
A28: Hauteur libre du plénum des couloirs (mm) | B28: 600 | C28: Maquette : faux plafond 2,50 / 5,86 m, sous-face de dalle 3,16 / 6,52 m
A29: Hauteur des gaines CTA 5 au-delà de 4 000 m³/h (mm) | B29: 350 | C29: Hypothèse équipe : tronc RDC de la CTA 5 (2 gaines côte à côte dans un couloir de 1,90 m), axe à 2,765 m : dessous à 2,59 m (faux plafond 2,57 m), dessus à 2,94 m (poutres 20x40 à 2,96 m)
A30: Vitesse maxi des gaines CTA 5 (m/s) | B30: 6 | C30: Hypothèse équipe : au-delà de 6 000 m³/h on garde 6 m/s, sinon la gaine serait plus étroite en amont qu'en aval
A32: • Tracé v2 : chaque CTA est posée juste au-dessus de sa descente. CTA 1, 2 et 5 : gaine technique créée dans un local annexe (ménage, office) car le DCE n'a que des gaines de désenfumage. CTA 3 et 4 (étage seul) : descente directe par la toiture dans le couloir.
A33: • Gaines horizontales uniquement dans les couloirs (et le hall / la salle à manger pour la CTA 5), parallèles aux murs, changements de direction à 90°. Axe des gaines à 2,78 m (RDC) et 6,14 m (étage) ; CTA 5 : 2,765 m (RDC) et 6,09 m (étage). CTA 3 et 4 : soufflage et reprise écartés de 1,0 m et 0,7 m pour laisser passer les antennes des bouches. CTA 5 RDC : la reprise passe au-dessus du faux plafond des bureaux côté sud (y = 34,4 m), le couloir garde seulement le soufflage.
A34: • Débits : 90 m³/h soufflés par chambre et 90 m³/h repris par salle de bains (CCTP § 2.2 et § 4.10) ; locaux communs : onglet « Débits par local » du fichier des débits.
A35: • La reprise suit le soufflage à côté, avec les mêmes débits. Les branches (CTA 5 vers le hall et la salle à manger de l'étage) sont en soufflage seul : la reprise de ces locaux se fait par transfert vers la circulation (hypothèse équipe).
A36: • Chaque tronçon va d'un piquage au suivant : son débit = somme des locaux desservis en aval.
A37: • Pertes de charge linéaires : formule de Darcy, coefficient λ de Swamee-Jain, diamètre équivalent des gaines rectangulaires De = 1,3·(a·b)^0,625 / (a+b)^0,25.

Sheet Tronçons
A1: Dimensionnement des gaines principales v2, tronçon par tronçon (soufflage et reprise)
A2: Débit en bleu = donnée (somme des locaux en aval). Le reste est calculé. X = tronçon du circuit le plus défavorisé.
A4: Réseau | B4: Repère | C4: Niveau | D4: Type | E4: Système | F4: Ce que dessert le tronçon (fin de tronçon) | G4: Longueur (m) | H4: Débit (m³/h) | I4: Vitesse maxi CCTP (m/s) | J4: Section mini (m²) | K4: Hauteur H (mm) | L4: Largeur L (mm) | M4: Section réelle (m²) | N4: Vitesse réelle (m/s) | O4: Vitesse OK ? | P4: Diamètre équivalent (m) | Q4: Reynolds | R4: λ | S4: Perte linéaire (Pa/m) | T4: Pertes du tronçon (Pa) | U4: Circuit défavorisé | V4: Passe dans le plénum ?
A5: CTA 1 | B5: CTA1-S01 | C5: Toiture | D5: Toiture (CTA → descente) | E5: Soufflage | F5: Sortie CTA → descente (trémie en toiture) | G5: 2.2 | H5: 2520 | I5: =IF(A5="CTA 5",MIN(INDEX(Hypothèses!$C$6:$C$16,MATCH(H5,Hypothèses!$A$6:$A$16,1)),Hypothèses!$B$30),INDEX(Hypothèses!$C$6:$C$16,MATCH(H5,Hypothèses!$A$6:$A$16,1))) | J5: =H5/3600/I5 | K5: =IF(A5="CTA 4",Hypothèses!$B$25,IF(AND(A5="CTA 5",H5>4000),Hypothèses!$B$29,IF(H5<=2000,Hypothèses!$B$23,Hypothèses!$B$24))) | L5: =MAX(Hypothèses!$B$26,CEILING(J5/(K5/1000)*1000,Hypothèses!$B$27)) | M5: =L5*K5/1000000 | N5: =H5/3600/M5 | O5: =IF(N5<=I5,"oui","NON") | P5: =1.3*((L5/1000)*(K5/1000))^0.625/((L5/1000)+(K5/1000))^0.25 | Q5: =N5*P5/Hypothèses!$B$20 | R5: =0.25/(LOG10(Hypothèses!$B$21/(3.7*P5)+5.74/Q5^0.9))^2 | S5: =R5/P5*Hypothèses!$B$19*N5^2/2 | T5: =S5*G5*(1+Hypothèses!$B$22) | U5: X | V5: –
A6: CTA 1 | B6: CTA1-S02 | C6: N01 | D6: Descente verticale | E6: Soufflage | F6: Gaine verticale : toiture → plénum étage | G6: 1.53 | H6: 2520 | I6: =IF(A6="CTA 5",MIN(INDEX(Hypothèses!$C$6:$C$16,MATCH(H6,Hypothèses!$A$6:$A$16,1)),Hypothèses!$B$30),INDEX(Hypothèses!$C$6:$C$16,MATCH(H6,Hypothèses!$A$6:$A$16,1))) | J6: =H6/3600/I6 | K6: =IF(A6="CTA 4",Hypothèses!$B$25,IF(AND(A6="CTA 5",H6>4000),Hypothèses!$B$29,IF(H6<=2000,Hypothèses!$B$23,Hypothèses!$B$24))) | L6: =MAX(Hypothèses!$B$26,CEILING(J6/(K6/1000)*1000,Hypothèses!$B$27)) | M6: =L6*K6/1000000 | N6: =H6/3600/M6 | O6: =IF(N6<=I6,"oui","NON") | P6: =1.3*((L6/1000)*(K6/1000))^0.625/((L6/1000)+(K6/1000))^0.25 | Q6: =N6*P6/Hypothèses!$B$20 | R6: =0.25/(LOG10(Hypothèses!$B$21/(3.7*P6)+5.74/Q6^0.9))^2 | S6: =R6/P6*Hypothèses!$B$19*N6^2/2 | T6: =S6*G6*(1+Hypothèses!$B$22) | U6: X | V6: –
A7: CTA 1 | B7: CTA1-S03 | C7: N00 | D7: Descente verticale | E7: Soufflage | F7: Gaine verticale : étage → plénum RDC | G7: 3.36 | H7: 1260 | I7: =IF(A7="CTA 5",MIN(INDEX(Hypothèses!$C$6:$C$16,MATCH(H7,Hypothèses!$A$6:$A$16,1)),Hypothèses!$B$30),INDEX(Hypothèses!$C$6:$C$16,MATCH(H7,Hypothèses!$A$6:$A$16,1))) | J7: =H7/3600/I7 | K7: =IF(A7="CTA 4",Hypothèses!$B$25,IF(AND(A7="CTA 5",H7>4000),Hypothèses!$B$29,IF(H7<=2000,Hypothèses!$B$23,Hypothèses!$B$24))) | L7: =MAX(Hypothèses!$B$26,CEILING(J7/(K7/1000)*1000,Hypothèses!$B$27)) | M7: =L7*K7/1000000 | N7: =H7/3600/M7 | O7: =IF(N7<=I7,"oui","NON") | P7: =1.3*((L7/1000)*(K7/1000))^0.625/((L7/1000)+(K7/1000))^0.25 | Q7: =N7*P7/Hypothèses!$B$20 | R7: =0.25/(LOG10(Hypothèses!$B$21/(3.7*P7)+5.74/Q7^0.9))^2 | S7: =R7/P7*Hypothèses!$B$19*N7^2/2 | T7: =S7*G7*(1+Hypothèses!$B$22) | U7: X | V7: –
A8: CTA 1 | B8: CTA1-S04 | C8: N01 | D8: Faux plafond couloir | E8: Soufflage | G8: 2.45 | H8: 1260 | I8: =IF(A8="CTA 5",MIN(INDEX(Hypothèses!$C$6:$C$16,MATCH(H8,Hypothèses!$A$6:$A$16,1)),Hypothèses!$B$30),INDEX(Hypothèses!$C$6:$C$16,MATCH(H8,Hypothèses!$A$6:$A$16,1))) | J8: =H8/3600/I8 | K8: =IF(A8="CTA 4",Hypothèses!$B$25,IF(AND(A8="CTA 5",H8>4000),Hypothèses!$B$29,IF(H8<=2000,Hypothèses!$B$23,Hypothèses!$B$24))) | L8: =MAX(Hypothèses!$B$26,CEILING(J8/(K8/1000)*1000,Hypothèses!$B$27)) | M8: =L8*K8/1000000 | N8: =H8/3600/M8 | O8: =IF(N8<=I8,"oui","NON") | P8: =1.3*((L8/1000)*(K8/1000))^0.625/((L8/1000)+(K8/1000))^0.25 | Q8: =N8*P8/Hypothèses!$B$20 | R8: =0.25/(LOG10(Hypothèses!$B$21/(3.7*P8)+5.74/Q8^0.9))^2 | S8: =R8/P8*Hypothèses!$B$19*N8^2/2 | T8: =S8*G8*(1+Hypothèses!$B$22) | V8: =IF(K8<=Hypothèses!$B$28-100,"oui","NON")
A9: CTA 1 | B9: CTA1-S05 | C9: N01 | D9: Faux plafond couloir | E9: Soufflage | F9: HEB01 chambre | G9: 1.3 | H9: 1260 | I9: =IF(A9="CTA 5",MIN(INDEX(Hypothèses!$C$6:$C$16,MATCH(H9,Hypothèses!$A$6:$A$16,1)),Hypothèses!$B$30),INDEX(Hypothèses!$C$6:$C$16,MATCH(H9,Hypothèses!$A$6:$A$16,1))) | J9: =H9/3600/I9 | K9: =IF(A9="CTA 4",Hypothèses!$B$25,IF(AND(A9="CTA 5",H9>4000),Hypothèses!$B$29,IF(H9<=2000,Hypothèses!$B$23,Hypothèses!$B$24))) | L9: =MAX(Hypothèses!$B$26,CEILING(J9/(K9/1000)*1000,Hypothèses!$B$27)) | M9: =L9*K9/1000000 | N9: =H9/3600/M9 | O9: =IF(N9<=I9,"oui","NON") | P9: =1.3*((L9/1000)*(K9/1000))^0.625/((L9/1000)+(K9/1000))^0.25 | Q9: =N9*P9/Hypothèses!$B$20 | R9: =0.25/(LOG10(Hypothèses!$B$21/(3.7*P9)+5.74/Q9^0.9))^2 | S9: =R9/P9*Hypothèses!$B$19*N9^2/2 | T9: =S9*G9*(1+Hypothèses!$B$22) | V9: =IF(K9<=Hypothèses!$B$28-100,"oui","NON")
A10: CTA 1 | B10: CTA1-S06 | C10: N01 | D10: Faux plafond couloir | E10: Soufflage | F10: HEB01 chambre | G10: 2.25 | H10: 1170 | I10: =IF(A10="CTA 5",MIN(INDEX(Hypothèses!$C$6:$C$16,MATCH(H10,Hypothèses!$A$6:$A$16,1)),Hypothèses!$B$30),INDEX(Hypothèses!$C$6:$C$16,MATCH(H10,Hypothèses!$A$6:$A$16,1))) | J10: =H10/3600/I10 | K10: =IF(A10="CTA 4",Hypothèses!$B$25,IF(AND(A10="CTA 5",H10>4000),Hypothèses!$B$29,IF(H10<=2000,Hypothèses!$B$23,Hypothèses!$B$24))) | L10: =MAX(Hypothèses!$B$26,CEILING(J10/(K10/1000)*1000,Hypothèses!$B$27)) | M10: =L10*K10/1000000 | N10: =H10/3600/M10 | O10: =IF(N10<=I10,"oui","NON") | P10: =1.3*((L10/1000)*(K10/1000))^0.625/((L10/1000)+(K10/1000))^0.25 | Q10: =N10*P10/Hypothèses!$B$20 | R10: =0.25/(LOG10(Hypothèses!$B$21/(3.7*P10)+5.74/Q10^0.9))^2 | S10: =R10/P10*Hypothèses!$B$19*N10^2/2 | T10: =S10*G10*(1+Hypothèses!$B$22) | V10: =IF(K10<=Hypothèses!$B$28-100,"oui","NON")
A11: CTA 1 | B11: CTA1-S07 | C11: N01 | D11: Faux plafond couloir | E11: Soufflage | F11: HEB01 chambre | G11: 3.551 | H11: 1170 | I11: =IF(A11="CTA 5",MIN(INDEX(Hypothèses!$C$6:$C$16,MATCH(H11,Hypothèses!$A$6:$A$16,1)),Hypothèses!$B$30),INDEX(Hypothèses!$C$6:$C$16,MATCH(H11,Hypothèses!$A$6:$A$16,1))) | J11: =H11/3600/I11 | K11: =IF(A11="CTA 4",Hypothèses!$B$25,IF(AND(A11="CTA 5",H11>4000),Hypothèses!$B$29,IF(H11<=2000,Hypothèses!$B$23,Hypothèses!$B$24))) | L11: =MAX(Hypothèses!$B$26,CEILING(J11/(K11/1000)*1000,Hypothèses!$B$27)) | M11: =L11*K11/1000000 | N11: =H11/3600/M11 | O11: =IF(N11<=I11,"oui","NON") | P11: =1.3*((L11/1000)*(K11/1000))^0.625/((L11/1000)+(K11/1000))^0.25 | Q11: =N11*P11/Hypothèses!$B$20 | R11: =0.25/(LOG10(Hypothèses!$B$21/(3.7*P11)+5.74/Q11^0.9))^2 | S11: =R11/P11*Hypothèses!$B$19*N11^2/2 | T11: =S11*G11*(1+Hypothèses!$B$22) | V11: =IF(K11<=Hypothèses!$B$28-100,"oui","NON")
A12: CTA 1 | B12: CTA1-S08 | C12: N01 | D12: Faux plafond couloir | E12: Soufflage | F12: HEB01 chambre | G12: 0.842 | H12: 990 | I12: =IF(A12="CTA 5",MIN(INDEX(Hypothèses!$C$6:$C$16,MATCH(H12,Hypothèses!$A$6:$A$16,1)),Hypothèses!$B$30),INDEX(Hypothèses!$C$6:$C$16,MATCH(H12,Hypothèses!$A$6:$A$16,1))) | J12: =H12/3600/I12 | K12: =IF(A12="CTA 4",Hypothèses!$B$25,IF(AND(A12="CTA 5",H12>4000),Hypothèses!$B$29,IF(H12<=2000,Hypothèses!$B$23,Hypothèses!$B$24))) | L12: =MAX(Hypothèses!$B$26,CEILING(J12/(K12/1000)*1000,Hypothèses!$B$27)) | M12: =L12*K12/1000000 | N12: =H12/3600/M12 | O12: =IF(N12<=I12,"oui","NON") | P12: =1.3*((L12/1000)*(K12/1000))^0.625/((L12/1000)+(K12/1000))^0.25 | Q12: =N12*P12/Hypothèses!$B$20 | R12: =0.25/(LOG10(Hypothèses!$B$21/(3.7*P12)+5.74/Q12^0.9))^2 | S12: =R12/P12*Hypothèses!$B$19*N12^2/2 | T12: =S12*G12*(1+Hypothèses!$B$22) | V12: =IF(K12<=Hypothèses!$B$28-100,"oui","NON")
A13: CTA 1 | B13: CTA1-S09 | C13: N01 | D13: Faux plafond couloir | E13: Soufflage | F13: HEB01 chambre | G13: 3.633 | H13: 900 | I13: =IF(A13="CTA 5",MIN(INDEX(Hypothèses!$C$6:$C$16,MATCH(H13,Hypothèses!$A$6:$A$16,1)),Hypothèses!$B$30),INDEX(Hypothèses!$C$6:$C$16,MATCH(H13,Hypothèses!$A$6:$A$16,1))) | J13: =H13/3600/I13 | K13: =IF(A13="CTA 4",Hypothèses!$B$25,IF(AND(A13="CTA 5",H13>4000),Hypothèses!$B$29,IF(H13<=2000,Hypothèses!$B$23,Hypothèses!$B$24))) | L13: =MAX(Hypothèses!$B$26,CEILING(J13/(K13/1000)*1000,Hypothèses!$B$27)) | M13: =L13*K13/1000000 | N13: =H13/3600/M13 | O13: =IF(N13<=I13,"oui","NON") | P13: =1.3*((L13/1000)*(K13/1000))^0.625/((L13/1000)+(K13/1000))^0.25 | Q13: =N13*P13/Hypothèses!$B$20 | R13: =0.25/(LOG10(Hypothèses!$B$21/(3.7*P13)+5.74/Q13^0.9))^2 | S13: =R13/P13*Hypothèses!$B$19*N13^2/2 | T13: =S13*G13*(1+Hypothèses!$B$22) | V13: =IF(K13<=Hypothèses!$B$28-100,"oui","NON")
A14: CTA 1 | B14: CTA1-S10 | C14: N01 | D14: Faux plafond couloir | E14: Soufflage | F14: HEB01 ch. couple | G14: 0.411 | H14: 810 | I14: =IF(A14="CTA 5",MIN(INDEX(Hypothèses!$C$6:$C$16,MATCH(H14,Hypothèses!$A$6:$A$16,1)),Hypothèses!$B$30),INDEX(Hypothèses!$C$6:$C$16,MATCH(H14,Hypothèses!$A$6:$A$16,1))) | J14: =H14/3600/I14 | K14: =IF(A14="CTA 4",Hypothèses!$B$25,IF(AND(A14="CTA 5",H14>4000),Hypothèses!$B$29,IF(H14<=2000,Hypothèses!$B$23,Hypothèses!$B$24))) | L14: =MAX(Hypothèses!$B$26,CEILING(J14/(K14/1000)*1000,Hypothèses!$B$27)) | M14: =L14*K14/1000000 | N14: =H14/3600/M14 | O14: =IF(N14<=I14,"oui","NON") | P14: =1.3*((L14/1000)*(K14/1000))^0.625/((L14/1000)+(K14/1000))^0.25 | Q14: =N14*P14/Hypothèses!$B$20 | R14: =0.25/(LOG10(Hypothèses!$B$21/(3.7*P14)+5.74/Q14^0.9))^2 | S14: =R14/P14*Hypothèses!$B$19*N14^2/2 | T14: =S14*G14*(1+Hypothèses!$B$22) | V14: =IF(K14<=Hypothèses!$B$28-100,"oui","NON")
A15: CTA 1 | B15: CTA1-S11 | C15: N01 | D15: Faux plafond couloir | E15: Soufflage | F15: HEB01 ch. couple | G15: 4.19 | H15: 810 | I15: =IF(A15="CTA 5",MIN(INDEX(Hypothèses!$C$6:$C$16,MATCH(H15,Hypothèses!$A$6:$A$16,1)),Hypothèses!$B$30),INDEX(Hypothèses!$C$6:$C$16,MATCH(H15,Hypothèses!$A$6:$A$16,1))) | J15: =H15/3600/I15 | K15: =IF(A15="CTA 4",Hypothèses!$B$25,IF(AND(A15="CTA 5",H15>4000),Hypothèses!$B$29,IF(H15<=2000,Hypothèses!$B$23,Hypothèses!$B$24))) | L15: =MAX(Hypothèses!$B$26,CEILING(J15/(K15/1000)*1000,Hypothèses!$B$27)) | M15: =L15*K15/1000000 | N15: =H15/3600/M15 | O15: =IF(N15<=I15,"oui","NON") | P15: =1.3*((L15/1000)*(K15/1000))^0.625/((L15/1000)+(K15/1000))^0.25 | Q15: =N15*P15/Hypothèses!$B$20 | R15: =0.25/(LOG10(Hypothèses!$B$21/(3.7*P15)+5.74/Q15^0.9))^2 | S15: =R15/P15*Hypothèses!$B$19*N15^2/2 | T15: =S15*G15*(1+Hypothèses!$B$22) | V15: =IF(K15<=Hypothèses!$B$28-100,"oui","NON")
A16: CTA 1 | B16: CTA1-S12 | C16: N01 | D16: Faux plafond couloir | E16: Soufflage | F16: HEB01 chambre | G16: 1.792 | H16: 630 | I16: =IF(A16="CTA 5",MIN(INDEX(Hypothèses!$C$6:$C$16,MATCH(H16,Hypothèses!$A$6:$A$16,1)),Hypothèses!$B$30),INDEX(Hypothèses!$C$6:$C$16,MATCH(H16,Hypothèses!$A$6:$A$16,1))) | J16: =H16/3600/I16 | K16: =IF(A16="CTA 4",Hypothèses!$B$25,IF(AND(A16="CTA 5",H16>4000),Hypothèses!$B$29,IF(H16<=2000,Hypothèses!$B$23,Hypothèses!$B$24))) | L16: =MAX(Hypothèses!$B$26,CEILING(J16/(K16/1000)*1000,Hypothèses!$B$27)) | M16: =L16*K16/1000000 | N16: =H16/3600/M16 | O16: =IF(N16<=I16,"oui","NON") | P16: =1.3*((L16/1000)*(K16/1000))^0.625/((L16/1000)+(K16/1000))^0.25 | Q16: =N16*P16/Hypothèses!$B$20 | R16: =0.25/(LOG10(Hypothèses!$B$21/(3.7*P16)+5.74/Q16^0.9))^2 | S16: =R16/P16*Hypothèses!$B$19*N16^2/2 | T16: =S16*G16*(1+Hypothèses!$B$22) | V16: =IF(K16<=Hypothèses!$B$28-100,"oui","NON")
A17: CTA 1 | B17: CTA1-S13 | C17: N01 | D17: Faux plafond couloir | E17: Soufflage | F17: HEB01 chambre | G17: 2.925 | H17: 540 | I17: =IF(A17="CTA 5",MIN(INDEX(Hypothèses!$C$6:$C$16,MATCH(H17,Hypothèses!$A$6:$A$16,1)),Hypothèses!$B$30),INDEX(Hypothèses!$C$6:$C$16,MATCH(H17,Hypothèses!$A$6:$A$16,1))) | J17: =H17/3600/I17 | K17: =IF(A17="CTA 4",Hypothèses!$B$25,IF(AND(A17="CTA 5",H17>4000),Hypothèses!$B$29,IF(H17<=2000,Hypothèses!$B$23,Hypothèses!$B$24))) | L17: =MAX(Hypothèses!$B$26,CEILING(J17/(K17/1000)*1000,Hypothèses!$B$27)) | M17: =L17*K17/1000000 | N17: =H17/3600/M17 | O17: =IF(N17<=I17,"oui","NON") | P17: =1.3*((L17/1000)*(K17/1000))^0.625/((L17/1000)+(K17/1000))^0.25 | Q17: =N17*P17/Hypothèses!$B$20 | R17: =0.25/(LOG10(Hypothèses!$B$21/(3.7*P17)+5.74/Q17^0.9))^2 | S17: =R17/P17*Hypothèses!$B$19*N17^2/2 | T17: =S17*G17*(1+Hypothèses!$B$22) | V17: =IF(K17<=Hypothèses!$B$28-100,"oui","NON")
A18: CTA 1 | B18: CTA1-S14 | C18: N01 | D18: Faux plafond couloir | E18: Soufflage | F18: HEB01 chambre | G18: 1.545 | H18: 540 | I18: =IF(A18="CTA 5",MIN(INDEX(Hypothèses!$C$6:$C$16,MATCH(H18,Hypothèses!$A$6:$A$16,1)),Hypothèses!$B$30),INDEX(Hypothèses!$C$6:$C$16,MATCH(H18,Hypothèses!$A$6:$A$16,1))) | J18: =H18/3600/I18 | K18: =IF(A18="CTA 4",Hypothèses!$B$25,IF(AND(A18="CTA 5",H18>4000),Hypothèses!$B$29,IF(H18<=2000,Hypothèses!$B$23,Hypothèses!$B$24))) | L18: =MAX(Hypothèses!$B$26,CEILING(J18/(K18/1000)*1000,Hypothèses!$B$27)) | M18: =L18*K18/1000000 | N18: =H18/3600/M18 | O18: =IF(N18<=I18,"oui","NON") | P18: =1.3*((L18/1000)*(K18/1000))^0.625/((L18/1000)+(K18/1000))^0.25 | Q18: =N18*P18/Hypothèses!$B$20 | R18: =0.25/(LOG10(Hypothèses!$B$21/(3.7*P18)+5.74/Q18^0.9))^2 | S18: =R18/P18*Hypothèses!$B$19*N18^2/2 | T18: =S18*G18*(1+Hypothèses!$B$22) | V18: =IF(K18<=Hypothèses!$B$28-100,"oui","NON")
A19: CTA 1 | B19: CTA1-S15 | C19: N01 | D19: Faux plafond couloir | E19: Soufflage | F19: HEB01 chambre | G19: 2.193 | H19: 450 | I19: =IF(A19="CTA 5",MIN(INDEX(Hypothèses!$C$6:$C$16,MATCH(H19,Hypothèses!$A$6:$A$16,1)),Hypothèses!$B$30),INDEX(Hypothèses!$C$6:$C$16,MATCH(H19,Hypothèses!$A$6:$A$16,1))) | J19: =H19/3600/I19 | K19: =IF(A19="CTA 4",Hypothèses!$B$25,IF(AND(A19="CTA 5",H19>4000),Hypothèses!$B$29,IF(H19<=2000,Hypothèses!$B$23,Hypothèses!$B$24))) | L19: =MAX(Hypothèses!$B$26,CEILING(J19/(K19/1000)*1000,Hypothèses!$B$27)) | M19: =L19*K19/1000000 | N19: =H19/3600/M19 | O19: =IF(N19<=I19,"oui","NON") | P19: =1.3*((L19/1000)*(K19/1000))^0.625/((L19/1000)+(K19/1000))^0.25 | Q19: =N19*P19/Hypothèses!$B$20 | R19: =0.25/(LOG10(Hypothèses!$B$21/(3.7*P19)+5.74/Q19^0.9))^2 | S19: =R19/P19*Hypothèses!$B$19*N19^2/2 | T19: =S19*G19*(1+Hypothèses!$B$22) | V19: =IF(K19<=Hypothèses!$B$28-100,"oui","NON")
A20: CTA 1 | B20: CTA1-S16 | C20: N01 | D20: Faux plafond couloir | E20: Soufflage | F20: HEB01 chambre | G20: 1.567 | H20: 270 | I20: =IF(A20="CTA 5",MIN(INDEX(Hypothèses!$C$6:$C$16,MATCH(H20,Hypothèses!$A$6:$A$16,1)),Hypothèses!$B$30),INDEX(Hypothèses!$C$6:$C$16,MATCH(H20,Hypothèses!$A$6:$A$16,1))) | J20: =H20/3600/I20 | K20: =IF(A20="CTA 4",Hypothèses!$B$25,IF(AND(A20="CTA 5",H20>4000),Hypothèses!$B$29,IF(H20<=2000,Hypothèses!$B$23,Hypothèses!$B$24))) | L20: =MAX(Hypothèses!$B$26,CEILING(J20/(K20/1000)*1000,Hypothèses!$B$27)) | M20: =L20*K20/1000000 | N20: =H20/3600/M20 | O20: =IF(N20<=I20,"oui","NON") | P20: =1.3*((L20/1000)*(K20/1000))^0.625/((L20/1000)+(K20/1000))^0.25 | Q20: =N20*P20/Hypothèses!$B$20 | R20: =0.25/(LOG10(Hypothèses!$B$21/(3.7*P20)+5.74/Q20^0.9))^2 | S20: =R20/P20*Hypothèses!$B$19*N20^2/2 | T20: =S20*G20*(1+Hypothèses!$B$22) | V20: =IF(K20<=Hypothèses!$B$28-100,"oui","NON")
... A22: CTA 1 | B22: CTA1-S18 | C22: N01 | D22: Faux plafond couloir | E22: Soufflage | F22: HEB01 chambre | G22: 1.633 | H22: 180 | I22: =IF(A22="CTA 5",MIN(INDEX(Hypothèses!$C$6:$C$16,MATCH(H22,Hypothèses!$A$6:$A$16,1)),Hypothèses!$B$30),INDEX(Hypothèses!$C$6:$C$16,MATCH(H22,Hypothèses!$A$6:$A$16,1))) | J22: =H22/3600/I22 | K22: =IF(A22="CTA 4",Hypothèses!$B$25,IF(AND(A22="CTA 5",H22>4000),Hypothèses!$B$29,IF(H22<=2000,Hypothèses!$B$23,Hypothèses!$B$24))) | L22: =MAX(Hypothèses!$B$26,CEILING(J22/(K22/1000)*1000,Hypothèses!$B$27)) | M22: =L22*K22/1000000 | N22: =H22/3600/M22 | O22: =IF(N22<=I22,"oui","NON") | P22: =1.3*((L22/1000)*(K22/1000))^0.625/((L22/1000)+(K22/1000))^0.25 | Q22: =N22*P22/Hypothèses!$B$20 | R22: =0.25/(LOG10(Hypothèses!$B$21/(3.7*P22)+5.74/Q22^0.9))^2 | S22: =R22/P22*Hypothèses!$B$19*N22^2/2 | T22: =S22*G22*(1+Hypothèses!$B$22) | V22: =IF(K22<=Hypothèses!$B$28-100,"oui","NON")
A23: CTA 1 | B23: CTA1-S19 | C23: N01 | D23: Faux plafond couloir | E23: Soufflage | G23: 1.427 | H23: 90 | I23: =IF(A23="CTA 5",MIN(INDEX(Hypothèses!$C$6:$C$16,MATCH(H23,Hypothèses!$A$6:$A$16,1)),Hypothèses!$B$30),INDEX(Hypothèses!$C$6:$C$16,MATCH(H23,Hypothèses!$A$6:$A$16,1))) | J23: =H23/3600/I23 | K23: =IF(A23="CTA 4",Hypothèses!$B$25,IF(AND(A23="CTA 5",H23>4000),Hypothèses!$B$29,IF(H23<=2000,Hypothèses!$B$23,Hypothèses!$B$24))) | L23: =MAX(Hypothèses!$B$26,CEILING(J23/(K23/1000)*1000,Hypothèses!$B$27)) | M23: =L23*K23/1000000 | N23: =H23/3600/M23 | O23: =IF(N23<=I23,"oui","NON") | P23: =1.3*((L23/1000)*(K23/1000))^0.625/((L23/1000)+(K23/1000))^0.25 | Q23: =N23*P23/Hypothèses!$B$20 | R23: =0.25/(LOG10(Hypothèses!$B$21/(3.7*P23)+5.74/Q23^0.9))^2 | S23: =R23/P23*Hypothèses!$B$19*N23^2/2 | T23: =S23*G23*(1+Hypothèses!$B$22) | V23: =IF(K23<=Hypothèses!$B$28-100,"oui","NON")
A24: CTA 1 | B24: CTA1-S20 | C24: N00 | D24: Faux plafond couloir | E24: Soufflage | G24: 2.45 | H24: 1260 | I24: =IF(A24="CTA 5",MIN(INDEX(Hypothèses!$C$6:$C$16,MATCH(H24,Hypothèses!$A$6:$A$16,1)),Hypothèses!$B$30),INDEX(Hypothèses!$C$6:$C$16,MATCH(H24,Hypothèses!$A$6:$A$16,1))) | J24: =H24/3600/I24 | K24: =IF(A24="CTA 4",Hypothèses!$B$25,IF(AND(A24="CTA 5",H24>4000),Hypothèses!$B$29,IF(H24<=2000,Hypothèses!$B$23,Hypothèses!$B$24))) | L24: =MAX(Hypothèses!$B$26,CEILING(J24/(K24/1000)*1000,Hypothèses!$B$27)) | M24: =L24*K24/1000000 | N24: =H24/3600/M24 | O24: =IF(N24<=I24,"oui","NON") | P24: =1.3*((L24/1000)*(K24/1000))^0.625/((L24/1000)+(K24/1000))^0.25 | Q24: =N24*P24/Hypothèses!$B$20 | R24: =0.25/(LOG10(Hypothèses!$B$21/(3.7*P24)+5.74/Q24^0.9))^2 | S24: =R24/P24*Hypothèses!$B$19*N24^2/2 | T24: =S24*G24*(1+Hypothèses!$B$22) | U24: X | V24: =IF(K24<=Hypothèses!$B$28-100,"oui","NON")
A25: CTA 1 | B25: CTA1-S21 | C25: N00 | D25: Faux plafond couloir | E25: Soufflage | F25: HEB01 chambre | G25: 1.3 | H25: 1260 | I25: =IF(A25="CTA 5",MIN(INDEX(Hypothèses!$C$6:$C$16,MATCH(H25,Hypothèses!$A$6:$A$16,1)),Hypothèses!$B$30),INDEX(Hypothèses!$C$6:$C$16,MATCH(H25,Hypothèses!$A$6:$A$16,1))) | J25: =H25/3600/I25 | K25: =IF(A25="CTA 4",Hypothèses!$B$25,IF(AND(A25="CTA 5",H25>4000),Hypothèses!$B$29,IF(H25<=2000,Hypothèses!$B$23,Hypothèses!$B$24))) | L25: =MAX(Hypothèses!$B$26,CEILING(J25/(K25/1000)*1000,Hypothèses!$B$27)) | M25: =L25*K25/1000000 | N25: =H25/3600/M25 | O25: =IF(N25<=I25,"oui","NON") | P25: =1.3*((L25/1000)*(K25/1000))^0.625/((L25/1000)+(K25/1000))^0.25 | Q25: =N25*P25/Hypothèses!$B$20 | R25: =0.25/(LOG10(Hypothèses!$B$21/(3.7*P25)+5.74/Q25^0.9))^2 | S25: =R25/P25*Hypothèses!$B$19*N25^2/2 | T25: =S25*G25*(1+Hypothèses!$B$22) | U25: X | V25: =IF(K25<=Hypothèses!$B$28-100,"oui","NON")
A26: CTA 1 | B26: CTA1-S22 | C26: N00 | D26: Faux plafond couloir | E26: Soufflage | F26: HEB01 chambre | G26: 2.25 | H26: 1170 | I26: =IF(A26="CTA 5",MIN(INDEX(Hypothèses!$C$6:$C$16,MATCH(H26,Hypothèses!$A$6:$A$16,1)),Hypothèses!$B$30),INDEX(Hypothèses!$C$6:$C$16,MATCH(H26,Hypothèses!$A$6:$A$16,1))) | J26: =H26/3600/I26 | K26: =IF(A26="CTA 4",Hypothèses!$B$25,IF(AND(A26="CTA 5",H26>4000),Hypothèses!$B$29,IF(H26<=2000,Hypothèses!$B$23,Hypothèses!$B$24))) | L26: =MAX(Hypothèses!$B$26,CEILING(J26/(K26/1000)*1000,Hypothèses!$B$27)) | M26: =L26*K26/1000000 | N26: =H26/3600/M26 | O26: =IF(N26<=I26,"oui","NON") | P26: =1.3*((L26/1000)*(K26/1000))^0.625/((L26/1000)+(K26/1000))^0.25 | Q26: =N26*P26/Hypothèses!$B$20 | R26: =0.25/(LOG10(Hypothèses!$B$21/(3.7*P26)+5.74/Q26^0.9))^2 | S26: =R26/P26*Hypothèses!$B$19*N26^2/2 | T26: =S26*G26*(1+Hypothèses!$B$22) | U26: X | V26: =IF(K26<=Hypothèses!$B$28-100,"oui","NON")
A27: CTA 1 | B27: CTA1-S23 | C27: N00 | D27: Faux plafond couloir | E27: Soufflage | F27: HEB01 chambre | G27: 3.551 | H27: 1080 | I27: =IF(A27="CTA 5",MIN(INDEX(Hypothèses!$C$6:$C$16,MATCH(H27,Hypothèses!$A$6:$A$16,1)),Hypothèses!$B$30),INDEX(Hypothèses!$C$6:$C$16,MATCH(H27,Hypothèses!$A$6:$A$16,1))) | J27: =H27/3600/I27 | K27: =IF(A27="CTA 4",Hypothèses!$B$25,IF(AND(A27="CTA 5",H27>4000),Hypothèses!$B$29,IF(H27<=2000,Hypothèses!$B$23,Hypothèses!$B$24))) | L27: =MAX(Hypothèses!$B$26,CEILING(J27/(K27/1000)*1000,Hypothèses!$B$27)) | M27: =L27*K27/1000000 | N27: =H27/3600/M27 | O27: =IF(N27<=I27,"oui","NON") | P27: =1.3*((L27/1000)*(K27/1000))^0.625/((L27/1000)+(K27/1000))^0.25 | Q27: =N27*P27/Hypothèses!$B$20 | R27: =0.25/(LOG10(Hypothèses!$B$21/(3.7*P27)+5.74/Q27^0.9))^2 | S27: =R27/P27*Hypothèses!$B$19*N27^2/2 | T27: =S27*G27*(1+Hypothèses!$B$22) | U27: X | V27: =IF(K27<=Hypothèses!$B$28-100,"oui","NON")
A28: CTA 1 | B28: CTA1-S24 | C28: N00 | D28: Faux plafond couloir | E28: Soufflage | F28: HEB01 chambre | G28: 0.842 | H28: 990 | I28: =IF(A28="CTA 5",MIN(INDEX(Hypothèses!$C$6:$C$16,MATCH(H28,Hypothèses!$A$6:$A$16,1)),Hypothèses!$B$30),INDEX(Hypothèses!$C$6:$C$16,MATCH(H28,Hypothèses!$A$6:$A$16,1))) | J28: =H28/3600/I28 | K28: =IF(A28="CTA 4",Hypothèses!$B$25,IF(AND(A28="CTA 5",H28>4000),Hypothèses!$B$29,IF(H28<=2000,Hypothèses!$B$23,Hypothèses!$B$24))) | L28: =MAX(Hypothèses!$B$26,CEILING(J28/(K28/1000)*1000,Hypothèses!$B$27)) | M28: =L28*K28/1000000 | N28: =H28/3600/M28 | O28: =IF(N28<=I28,"oui","NON") | P28: =1.3*((L28/1000)*(K28/1000))^0.625/((L28/1000)+(K28/1000))^0.25 | Q28: =N28*P28/Hypothèses!$B$20 | R28: =0.25/(LOG10(Hypothèses!$B$21/(3.7*P28)+5.74/Q28^0.9))^2 | S28: =R28/P28*Hypothèses!$B$19*N28^2/2 | T28: =S28*G28*(1+Hypothèses!$B$22) | U28: X | V28: =IF(K28<=Hypothèses!$B$28-100,"oui","NON")
A29: CTA 1 | B29: CTA1-S25 | C29: N00 | D29: Faux plafond couloir | E29: Soufflage | F29: HEB01 chambre | G29: 3.633 | H29: 900 | I29: =IF(A29="CTA 5",MIN(INDEX(Hypothèses!$C$6:$C$16,MATCH(H29,Hypothèses!$A$6:$A$16,1)),Hypothèses!$B$30),INDEX(Hypothèses!$C$6:$C$16,MATCH(H29,Hypothèses!$A$6:$A$16,1))) | J29: =H29/3600/I29 | K29: =IF(A29="CTA 4",Hypothèses!$B$25,IF(AND(A29="CTA 5",H29>4000),Hypothèses!$B$29,IF(H29<=2000,Hypothèses!$B$23,Hypothèses!$B$24))) | L29: =MAX(Hypothèses!$B$26,CEILING(J29/(K29/1000)*1000,Hypothèses!$B$27)) | M29: =L29*K29/1000000 | N29: =H29/3600/M29 | O29: =IF(N29<=I29,"oui","NON") | P29: =1.3*((L29/1000)*(K29/1000))^0.625/((L29/1000)+(K29/1000))^0.25 | Q29: =N29*P29/Hypothèses!$B$20 | R29: =0.25/(LOG10(Hypothèses!$B$21/(3.7*P29)+5.74/Q29^0.9))^2 | S29: =R29/P29*Hypothèses!$B$19*N29^2/2 | T29: =S29*G29*(1+Hypothèses!$B$22) | U29: X | V29: =IF(K29<=Hypothèses!$B$28-100,"oui","NON")
A30: CTA 1 | B30: CTA1-S26 | C30: N00 | D30: Faux plafond couloir | E30: Soufflage | F30: HEB01 ch. couple | G30: 0.412 | H30: 810 | I30: =IF(A30="CTA 5",MIN(INDEX(Hypothèses!$C$6:$C$16,MATCH(H30,Hypothèses!$A$6:$A$16,1)),Hypothèses!$B$30),INDEX(Hypothèses!$C$6:$C$16,MATCH(H30,Hypothèses!$A$6:$A$16,1))) | J30: =H30/3600/I30 | K30: =IF(A30="CTA 4",Hypothèses!$B$25,IF(AND(A30="CTA 5",H30>4000),Hypothèses!$B$29,IF(H30<=2000,Hypothèses!$B$23,Hypothèses!$B$24))) | L30: =MAX(Hypothèses!$B$26,CEILING(J30/(K30/1000)*1000,Hypothèses!$B$27)) | M30: =L30*K30/1000000 | N30: =H30/3600/M30 | O30: =IF(N30<=I30,"oui","NON") | P30: =1.3*((L30/1000)*(K30/1000))^0.625/((L30/1000)+(K30/1000))^0.25 | Q30: =N30*P30/Hypothèses!$B$20 | R30: =0.25/(LOG10(Hypothèses!$B$21/(3.7*P30)+5.74/Q30^0.9))^2 | S30: =R30/P30*Hypothèses!$B$19*N30^2/2 | T30: =S30*G30*(1+Hypothèses!$B$22) | U30: X | V30: =IF(K30<=Hypothèses!$B$28-100,"oui","NON")
A31: CTA 1 | B31: CTA1-S27 | C31: N00 | D31: Faux plafond couloir | E31: Soufflage | F31: HEB01 ch. couple | G31: 4.159 | H31: 720 | I31: =IF(A31="CTA 5",MIN(INDEX(Hypothèses!$C$6:$C$16,MATCH(H31,Hypothèses!$A$6:$A$16,1)),Hypothèses!$B$30),INDEX(Hypothèses!$C$6:$C$16,MATCH(H31,Hypothèses!$A$6:$A$16,1))) | J31: =H31/3600/I31 | K31: =IF(A31="CTA 4",Hypothèses!$B$25,IF(AND(A31="CTA 5",H31>4000),Hypothèses!$B$29,IF(H31<=2000,Hypothèses!$B$23,Hypothèses!$B$24))) | L31: =MAX(Hypothèses!$B$26,CEILING(J31/(K31/1000)*1000,Hypothèses!$B$27)) | M31: =L31*K31/1000000 | N31: =H31/3600/M31 | O31: =IF(N31<=I31,"oui","NON") | P31: =1.3*((L31/1000)*(K31/1000))^0.625/((L31/1000)+(K31/1000))^0.25 | Q31: =N31*P31/Hypothèses!$B$20 | R31: =0.25/(LOG10(Hypothèses!$B$21/(3.7*P31)+5.74/Q31^0.9))^2 | S31: =R31/P31*Hypothèses!$B$19*N31^2/2 | T31: =S31*G31*(1+Hypothèses!$B$22) | U31: X | V31: =IF(K31<=Hypothèses!$B$28-100,"oui","NON")
A32: CTA 1 | B32: CTA1-S28 | C32: N00 | D32: Faux plafond couloir | E32: Soufflage | F32: HEB01 chambre | G32: 1.823 | H32: 720 | I32: =IF(A32="CTA 5",MIN(INDEX(Hypothèses!$C$6:$C$16,MATCH(H32,Hypothèses!$A$6:$A$16,1)),Hypothèses!$B$30),INDEX(Hypothèses!$C$6:$C$16,MATCH(H32,Hypothèses!$A$6:$A$16,1))) | J32: =H32/3600/I32 | K32: =IF(A32="CTA 4",Hypothèses!$B$25,IF(AND(A32="CTA 5",H32>4000),Hypothèses!$B$29,IF(H32<=2000,Hypothèses!$B$23,Hypothèses!$B$24))) | L32: =MAX(Hypothèses!$B$26,CEILING(J32/(K32/1000)*1000,Hypothèses!$B$27)) | M32: =L32*K32/1000000 | N32: =H32/3600/M32 | O32: =IF(N32<=I32,"oui","NON") | P32: =1.3*((L32/1000)*(K32/1000))^0.625/((L32/1000)+(K32/1000))^0.25 | Q32: =N32*P32/Hypothèses!$B$20 | R32: =0.25/(LOG10(Hypothèses!$B$21/(3.7*P32)+5.74/Q32^0.9))^2 | S32: =R32/P32*Hypothèses!$B$19*N32^2/2 | T32: =S32*G32*(1+Hypothèses!$B$22) | U32: X | V32: =IF(K32<=Hypothèses!$B$28-100,"oui","NON")
A33: CTA 1 | B33: CTA1-S29 | C33: N00 | D33: Faux plafond couloir | E33: Soufflage | F33: HEB01 chambre | G33: 2.927 | H33: 540 | I33: =IF(A33="CTA 5",MIN(INDEX(Hypothèses!$C$6:$C$16,MATCH(H33,Hypothèses!$A$6:$A$16,1)),Hypothèses!$B$30),INDEX(Hypothèses!$C$6:$C$16,MATCH(H33,Hypothèses!$A$6:$A$16,1))) | J33: =H33/3600/I33 | K33: =IF(A33="CTA 4",Hypothèses!$B$25,IF(AND(A33="CTA 5",H33>4000),Hypothèses!$B$29,IF(H33<=2000,Hypothèses!$B$23,Hypothèses!$B$24))) | L33: =MAX(Hypothèses!$B$26,CEILING(J33/(K33/1000)*1000,Hypothèses!$B$27)) | M33: =L33*K33/1000000 | N33: =H33/3600/M33 | O33: =IF(N33<=I33,"oui","NON") | P33: =1.3*((L33/1000)*(K33/1000))^0.625/((L33/1000)+(K33/1000))^0.25 | Q33: =N33*P33/Hypothèses!$B$20 | R33: =0.25/(LOG10(Hypothèses!$B$21/(3.7*P33)+5.74/Q33^0.9))^2 | S33: =R33/P33*Hypothèses!$B$19*N33^2/2 | T33: =S33*G33*(1+Hypothèses!$B$22) | U33: X | V33: =IF(K33<=Hypothèses!$B$28-100,"oui","NON")
A34: CTA 1 | B34: CTA1-S30 | C34: N00 | D34: Faux plafond couloir | E34: Soufflage | F34: HEB01 chambre | G34: 1.542 | H34: 540 | I34: =IF(A34="CTA 5",MIN(INDEX(Hypothèses!$C$6:$C$16,MATCH(H34,Hypothèses!$A$6:$A$16,1)),Hypothèses!$B$30),INDEX(Hypothèses!$C$6:$C$16,MATCH(H34,Hypothèses!$A$6:$A$16,1))) | J34: =H34/3600/I34 | K34: =IF(A34="CTA 4",Hypothèses!$B$25,IF(AND(A34="CTA 5",H34>4000),Hypothèses!$B$29,IF(H34<=2000,Hypothèses!$B$23,Hypothèses!$B$24))) | L34: =MAX(Hypothèses!$B$26,CEILING(J34/(K34/1000)*1000,Hypothèses!$B$27)) | M34: =L34*K34/1000000 | N34: =H34/3600/M34 | O34: =IF(N34<=I34,"oui","NON") | P34: =1.3*((L34/1000)*(K34/1000))^0.625/((L34/1000)+(K34/1000))^0.25 | Q34: =N34*P34/Hypothèses!$B$20 | R34: =0.25/(LOG10(Hypothèses!$B$21/(3.7*P34)+5.74/Q34^0.9))^2 | S34: =R34/P34*Hypothèses!$B$19*N34^2/2 | T34: =S34*G34*(1+Hypothèses!$B$22) | U34: X | V34: =IF(K34<=Hypothèses!$B$28-100,"oui","NON")
A35: CTA 1 | B35: CTA1-S31 | C35: N00 | D35: Faux plafond couloir | E35: Soufflage | F35: HEB01 chambre | G35: 2.192 | H35: 450 | I35: =IF(A35="CTA 5",MIN(INDEX(Hypothèses!$C$6:$C$16,MATCH(H35,Hypothèses!$A$6:$A$16,1)),Hypothèses!$B$30),INDEX(Hypothèses!$C$6:$C$16,MATCH(H35,Hypothèses!$A$6:$A$16,1))) | J35: =H35/3600/I35 | K35: =IF(A35="CTA 4",Hypothèses!$B$25,IF(AND(A35="CTA 5",H35>4000),Hypothèses!$B$29,IF(H35<=2000,Hypothèses!$B$23,Hypothèses!$B$24))) | L35: =MAX(Hypothèses!$B$26,CEILING(J35/(K35/1000)*1000,Hypothèses!$B$27)) | M35: =L35*K35/1000000 | N35: =H35/3600/M35 | O35: =IF(N35<=I35,"oui","NON") | P35: =1.3*((L35/1000)*(K35/1000))^0.625/((L35/1000)+(K35/1000))^0.25 | Q35: =N35*P35/Hypothèses!$B$20 | R35: =0.25/(LOG10(Hypothèses!$B$21/(3.7*P35)+5.74/Q35^0.9))^2 | S35: =R35/P35*Hypothèses!$B$19*N35^2/2 | T35: =S35*G35*(1+Hypothèses!$B$22) | U35: X | V35: =IF(K35<=Hypothèses!$B$28-100,"oui","NON")
A36: CTA 1 | B36: CTA1-S32 | C36: N00 | D36: Faux plafond couloir | E36: Soufflage | F36: HEB01 chambre | G36: 1.57 | H36: 270 | I36: =IF(A36="CTA 5",MIN(INDEX(Hypothèses!$C$6:$C$16,MATCH(H36,Hypothèses!$A$6:$A$16,1)),Hypothèses!$B$30),INDEX(Hypothèses!$C$6:$C$16,MATCH(H36,Hypothèses!$A$6:$A$16,1))) | J36: =H36/3600/I36 | K36: =IF(A36="CTA 4",Hypothèses!$B$25,IF(AND(A36="CTA 5",H36>4000),Hypothèses!$B$29,IF(H36<=2000,Hypothèses!$B$23,Hypothèses!$B$24))) | L36: =MAX(Hypothèses!$B$26,CEILING(J36/(K36/1000)*1000,Hypothèses!$B$27)) | M36: =L36*K36/1000000 | N36: =H36/3600/M36 | O36: =IF(N36<=I36,"oui","NON") | P36: =1.3*((L36/1000)*(K36/1000))^0.625/((L36/1000)+(K36/1000))^0.25 | Q36: =N36*P36/Hypothèses!$B$20 | R36: =0.25/(LOG10(Hypothèses!$B$21/(3.7*P36)+5.74/Q36^0.9))^2 | S36: =R36/P36*Hypothèses!$B$19*N36^2/2 | T36: =S36*G36*(1+Hypothèses!$B$22) | U36: X | V36: =IF(K36<=Hypothèses!$B$28-100,"oui","NON")
... A38: CTA 1 | B38: CTA1-S34 | C38: N00 | D38: Faux plafond couloir | E38: Soufflage | F38: HEB01 chambre | G38: 1.634 | H38: 180 | I38: =IF(A38="CTA 5",MIN(INDEX(Hypothèses!$C$6:$C$16,MATCH(H38,Hypothèses!$A$6:$A$16,1)),Hypothèses!$B$30),INDEX(Hypothèses!$C$6:$C$16,MATCH(H38,Hypothèses!$A$6:$A$16,1))) | J38: =H38/3600/I38 | K38: =IF(A38="CTA 4",Hypothèses!$B$25,IF(AND(A38="CTA 5",H38>4000),Hypothèses!$B$29,IF(H38<=2000,Hypothèses!$B$23,Hypothèses!$B$24))) | L38: =MAX(Hypothèses!$B$26,CEILING(J38/(K38/1000)*1000,Hypothèses!$B$27)) | M38: =L38*K38/1000000 | N38: =H38/3600/M38 | O38: =IF(N38<=I38,"oui","NON") | P38: =1.3*((L38/1000)*(K38/1000))^0.625/((L38/1000)+(K38/1000))^0.25 | Q38: =N38*P38/Hypothèses!$B$20 | R38: =0.25/(LOG10(Hypothèses!$B$21/(3.7*P38)+5.74/Q38^0.9))^2 | S38: =R38/P38*Hypothèses!$B$19*N38^2/2 | T38: =S38*G38*(1+Hypothèses!$B$22) | U38: X | V38: =IF(K38<=Hypothèses!$B$28-100,"oui","NON")
A39: CTA 1 | B39: CTA1-S35 | C39: N00 | D39: Faux plafond couloir | E39: Soufflage | G39: 1.427 | H39: 90 | I39: =IF(A39="CTA 5",MIN(INDEX(Hypothèses!$C$6:$C$16,MATCH(H39,Hypothèses!$A$6:$A$16,1)),Hypothèses!$B$30),INDEX(Hypothèses!$C$6:$C$16,MATCH(H39,Hypothèses!$A$6:$A$16,1))) | J39: =H39/3600/I39 | K39: =IF(A39="CTA 4",Hypothèses!$B$25,IF(AND(A39="CTA 5",H39>4000),Hypothèses!$B$29,IF(H39<=2000,Hypothèses!$B$23,Hypothèses!$B$24))) | L39: =MAX(Hypothèses!$B$26,CEILING(J39/(K39/1000)*1000,Hypothèses!$B$27)) | M39: =L39*K39/1000000 | N39: =H39/3600/M39 | O39: =IF(N39<=I39,"oui","NON") | P39: =1.3*((L39/1000)*(K39/1000))^0.625/((L39/1000)+(K39/1000))^0.25 | Q39: =N39*P39/Hypothèses!$B$20 | R39: =0.25/(LOG10(Hypothèses!$B$21/(3.7*P39)+5.74/Q39^0.9))^2 | S39: =R39/P39*Hypothèses!$B$19*N39^2/2 | T39: =S39*G39*(1+Hypothèses!$B$22) | U39: X | V39: =IF(K39<=Hypothèses!$B$28-100,"oui","NON")
A40: CTA 1 | B40: CTA1-R36 | C40: Toiture | D40: Toiture (CTA → descente) | E40: Reprise | F40: Sortie CTA → descente (trémie en toiture) | G40: 3 | H40: 2520 | I40: =IF(A40="CTA 5",MIN(INDEX(Hypothèses!$C$6:$C$16,MATCH(H40,Hypothèses!$A$6:$A$16,1)),Hypothèses!$B$30),INDEX(Hypothèses!$C$6:$C$16,MATCH(H40,Hypothèses!$A$6:$A$16,1))) | J40: =H40/3600/I40 | K40: =IF(A40="CTA 4",Hypothèses!$B$25,IF(AND(A40="CTA 5",H40>4000),Hypothèses!$B$29,IF(H40<=2000,Hypothèses!$B$23,Hypothèses!$B$24))) | L40: =MAX(Hypothèses!$B$26,CEILING(J40/(K40/1000)*1000,Hypothèses!$B$27)) | M40: =L40*K40/1000000 | N40: =H40/3600/M40 | O40: =IF(N40<=I40,"oui","NON") | P40: =1.3*((L40/1000)*(K40/1000))^0.625/((L40/1000)+(K40/1000))^0.25 | Q40: =N40*P40/Hypothèses!$B$20 | R40: =0.25/(LOG10(Hypothèses!$B$21/(3.7*P40)+5.74/Q40^0.9))^2 | S40: =R40/P40*Hypothèses!$B$19*N40^2/2 | T40: =S40*G40*(1+Hypothèses!$B$22) | U40: X | V40: –
A41: CTA 1 | B41: CTA1-R37 | C41: N01 | D41: Descente verticale | E41: Reprise | F41: Gaine verticale : toiture → plénum étage | G41: 2.13 | H41: 2520 | I41: =IF(A41="CTA 5",MIN(INDEX(Hypothèses!$C$6:$C$16,MATCH(H41,Hypothèses!$A$6:$A$16,1)),Hypothèses!$B$30),INDEX(Hypothèses!$C$6:$C$16,MATCH(H41,Hypothèses!$A$6:$A$16,1))) | J41: =H41/3600/I41 | K41: =IF(A41="CTA 4",Hypothèses!$B$25,IF(AND(A41="CTA 5",H41>4000),Hypothèses!$B$29,IF(H41<=2000,Hypothèses!$B$23,Hypothèses!$B$24))) | L41: =MAX(Hypothèses!$B$26,CEILING(J41/(K41/1000)*1000,Hypothèses!$B$27)) | M41: =L41*K41/1000000 | N41: =H41/3600/M41 | O41: =IF(N41<=I41,"oui","NON") | P41: =1.3*((L41/1000)*(K41/1000))^0.625/((L41/1000)+(K41/1000))^0.25 | Q41: =N41*P41/Hypothèses!$B$20 | R41: =0.25/(LOG10(Hypothèses!$B$21/(3.7*P41)+5.74/Q41^0.9))^2 | S41: =R41/P41*Hypothèses!$B$19*N41^2/2 | T41: =S41*G41*(1+Hypothèses!$B$22) | U41: X | V41: –
A42: CTA 1 | B42: CTA1-R38 | C42: N00 | D42: Descente verticale | E42: Reprise | F42: Gaine verticale : étage → plénum RDC | G42: 3.36 | H42: 1260 | I42: =IF(A42="CTA 5",MIN(INDEX(Hypothèses!$C$6:$C$16,MATCH(H42,Hypothèses!$A$6:$A$16,1)),Hypothèses!$B$30),INDEX(Hypothèses!$C$6:$C$16,MATCH(H42,Hypothèses!$A$6:$A$16,1))) | J42: =H42/3600/I42 | K42: =IF(A42="CTA 4",Hypothèses!$B$25,IF(AND(A42="CTA 5",H42>4000),Hypothèses!$B$29,IF(H42<=2000,Hypothèses!$B$23,Hypothèses!$B$24))) | L42: =MAX(Hypothèses!$B$26,CEILING(J42/(K42/1000)*1000,Hypothèses!$B$27)) | M42: =L42*K42/1000000 | N42: =H42/3600/M42 | O42: =IF(N42<=I42,"oui","NON") | P42: =1.3*((L42/1000)*(K42/1000))^0.625/((L42/1000)+(K42/1000))^0.25 | Q42: =N42*P42/Hypothèses!$B$20 | R42: =0.25/(LOG10(Hypothèses!$B$21/(3.7*P42)+5.74/Q42^0.9))^2 | S42: =R42/P42*Hypothèses!$B$19*N42^2/2 | T42: =S42*G42*(1+Hypothèses!$B$22) | U42: X | V42: –
A43: CTA 1 | B43: CTA1-R39 | C43: N01 | D43: Faux plafond couloir | E43: Reprise | G43: 1.6 | H43: 1260 | I43: =IF(A43="CTA 5",MIN(INDEX(Hypothèses!$C$6:$C$16,MATCH(H43,Hypothèses!$A$6:$A$16,1)),Hypothèses!$B$30),INDEX(Hypothèses!$C$6:$C$16,MATCH(H43,Hypothèses!$A$6:$A$16,1))) | J43: =H43/3600/I43 | K43: =IF(A43="CTA 4",Hypothèses!$B$25,IF(AND(A43="CTA 5",H43>4000),Hypothèses!$B$29,IF(H43<=2000,Hypothèses!$B$23,Hypothèses!$B$24))) | L43: =MAX(Hypothèses!$B$26,CEILING(J43/(K43/1000)*1000,Hypothèses!$B$27)) | M43: =L43*K43/1000000 | N43: =H43/3600/M43 | O43: =IF(N43<=I43,"oui","NON") | P43: =1.3*((L43/1000)*(K43/1000))^0.625/((L43/1000)+(K43/1000))^0.25 | Q43: =N43*P43/Hypothèses!$B$20 | R43: =0.25/(LOG10(Hypothèses!$B$21/(3.7*P43)+5.74/Q43^0.9))^2 | S43: =R43/P43*Hypothèses!$B$19*N43^2/2 | T43: =S43*G43*(1+Hypothèses!$B$22) | V43: =IF(K43<=Hypothèses!$B$28-100,"oui","NON")
...

Sheet Réseaux VMC
A1: Réseaux VMC simple flux (CCTP lot 12 § 4.12) – gaines principales
A2: En bleu : données de la maquette (débit, section dessinée). Vitesse maxi : tableau de l'onglet Hypothèses (CCTP § 2.2.5). Gaines rondes : Ø315 au raccord du caisson.
A4: Réseau | B4: Niveau | C4: Type | D4: Tronçon | E4: Longueur (m) | F4: Débit (m³/h) | G4: Largeur L ou Ø (mm) | H4: Hauteur H (mm, 0 = rond) | I4: Section (m²) | J4: Vitesse (m/s) | K4: Vitesse maxi CCTP (m/s) | L4: Vitesse OK ?
A5: VMC 1 | B5: RDC | C5: Montée | D5: montée VMC RDC → étage | E5: 3.36 | F5: 1140 | G5: 400 | H5: 250 | I5: =IF(H5=0,PI()*(G5/1000)^2/4,G5*H5/1000000) | J5: =F5/3600/I5 | K5: =INDEX(Hypothèses!$C$6:$C$16,MATCH(F5,Hypothèses!$A$6:$A$16,1)) | L5: =IF(J5<=K5,"oui","NON")
A6: VMC 1 | B6: R+1 | C6: Montée | D6: montée VMC étage → toiture | E6: 1.18 | F6: 1785 | G6: 400 | H6: 250 | I6: =IF(H6=0,PI()*(G6/1000)^2/4,G6*H6/1000000) | J6: =F6/3600/I6 | K6: =INDEX(Hypothèses!$C$6:$C$16,MATCH(F6,Hypothèses!$A$6:$A$16,1)) | L6: =IF(J6<=K6,"oui","NON")
A7: VMC 1 | B7: Toiture | C7: Toiture | D7: toiture → caisson | E7: 1.34 | F7: 1785 | G7: 400 | H7: 250 | I7: =IF(H7=0,PI()*(G7/1000)^2/4,G7*H7/1000000) | J7: =F7/3600/I7 | K7: =INDEX(Hypothèses!$C$6:$C$16,MATCH(F7,Hypothèses!$A$6:$A$16,1)) | L7: =IF(J7<=K7,"oui","NON")
A8: VMC 1 | B8: Toiture | C8: Raccord caisson | D8: raccord caisson Ø315 | E8: 0.5 | F8: 1785 | G8: 315 | H8: 0 | I8: =IF(H8=0,PI()*(G8/1000)^2/4,G8*H8/1000000) | J8: =F8/3600/I8 | K8: =INDEX(Hypothèses!$C$6:$C$16,MATCH(F8,Hypothèses!$A$6:$A$16,1)) | L8: =IF(J8<=K8,"oui","NON")
A9: VMC 1 | B9: RDC | C9: Collecteur | D9: N00 collecteur nord | E9: 3.3 | F9: 1140 | G9: 400 | H9: 250 | I9: =IF(H9=0,PI()*(G9/1000)^2/4,G9*H9/1000000) | J9: =F9/3600/I9 | K9: =INDEX(Hypothèses!$C$6:$C$16,MATCH(F9,Hypothèses!$A$6:$A$16,1)) | L9: =IF(J9<=K9,"oui","NON")
A10: VMC 1 | B10: RDC | C10: Collecteur | D10: N00 collecteur | E10: 8.2 | F10: 1140 | G10: 400 | H10: 250 | I10: =IF(H10=0,PI()*(G10/1000)^2/4,G10*H10/1000000) | J10: =F10/3600/I10 | K10: =INDEX(Hypothèses!$C$6:$C$16,MATCH(F10,Hypothèses!$A$6:$A$16,1)) | L10: =IF(J10<=K10,"oui","NON")
A11: VMC 1 | B11: RDC | C11: Collecteur | D11: N00 collecteur sud | E11: 9 | F11: 750 | G11: 350 | H11: 150 | I11: =IF(H11=0,PI()*(G11/1000)^2/4,G11*H11/1000000) | J11: =F11/3600/I11 | K11: =INDEX(Hypothèses!$C$6:$C$16,MATCH(F11,Hypothèses!$A$6:$A$16,1)) | L11: =IF(J11<=K11,"oui","NON")
A12: VMC 1 | B12: R+1 | C12: Collecteur | D12: N01 collecteur nord | E12: 3.3 | F12: 645 | G12: 300 | H12: 150 | I12: =IF(H12=0,PI()*(G12/1000)^2/4,G12*H12/1000000) | J12: =F12/3600/I12 | K12: =INDEX(Hypothèses!$C$6:$C$16,MATCH(F12,Hypothèses!$A$6:$A$16,1)) | L12: =IF(J12<=K12,"oui","NON")
A13: VMC 1 | B13: R+1 | C13: Collecteur | D13: N01 collecteur | E13: 11.8 | F13: 645 | G13: 300 | H13: 150 | I13: =IF(H13=0,PI()*(G13/1000)^2/4,G13*H13/1000000) | J13: =F13/3600/I13 | K13: =INDEX(Hypothèses!$C$6:$C$16,MATCH(F13,Hypothèses!$A$6:$A$16,1)) | L13: =IF(J13<=K13,"oui","NON")
A14: VMC 2 | B14: RDC | C14: Montée | D14: montée VMC N00 → toiture | E14: 4.54 | F14: 315 | G14: 200 | H14: 150 | I14: =IF(H14=0,PI()*(G14/1000)^2/4,G14*H14/1000000) | J14: =F14/3600/I14 | K14: =INDEX(Hypothèses!$C$6:$C$16,MATCH(F14,Hypothèses!$A$6:$A$16,1)) | L14: =IF(J14<=K14,"oui","NON")
A15: VMC 2 | B15: Toiture | C15: Toiture | D15: toiture → caisson | E15: 3.1 | F15: 315 | G15: 200 | H15: 150 | I15: =IF(H15=0,PI()*(G15/1000)^2/4,G15*H15/1000000) | J15: =F15/3600/I15 | K15: =INDEX(Hypothèses!$C$6:$C$16,MATCH(F15,Hypothèses!$A$6:$A$16,1)) | L15: =IF(J15<=K15,"oui","NON")
A16: VMC 2 | B16: Toiture | C16: Toiture | D16: toiture → caisson | E16: 5.62 | F16: 315 | G16: 200 | H16: 150 | I16: =IF(H16=0,PI()*(G16/1000)^2/4,G16*H16/1000000) | J16: =F16/3600/I16 | K16: =INDEX(Hypothèses!$C$6:$C$16,MATCH(F16,Hypothèses!$A$6:$A$16,1)) | L16: =IF(J16<=K16,"oui","NON")
... A50: VMC 6 | B50: Toiture | C50: Raccord caisson | D50: raccord caisson Ø315 | E50: 0.5 | F50: 45 | G50: 315 | H50: 0 | I50: =IF(H50=0,PI()*(G50/1000)^2/4,G50*H50/1000000) | J50: =F50/3600/I50 | K50: =INDEX(Hypothèses!$C$6:$C$16,MATCH(F50,Hypothèses!$A$6:$A$16,1)) | L50: =IF(J50<=K50,"oui","NON")
A52: Synthèse par caisson
A53: Caisson | B53: Zone desservie | C53: Débit (m³/h) | D53: Nb de bouches | E53: Vitesse maxi dans le réseau (m/s) | F53: Tronçons hors vitesse
A54: VMC 1 | B54: Nord : offices, tisanerie, sanitaires, lingerie, ménage | C54: =SUMIFS($F$5:$F$50,$A$5:$A$50,A54,$C$5:$C$50,"Raccord caisson") | D54: 20 | E54: =_xlfn.MAXIFS($J$5:$J$50,$A$5:$A$50,A54) | F54: =COUNTIFS($A$5:$A$50,A54,$L$5:$L$50,"NON")
A55: VMC 2 | B55: Ouest RDC : vestiaires, douches, WC, ménage | C55: =SUMIFS($F$5:$F$50,$A$5:$A$50,A55,$C$5:$C$50,"Raccord caisson") | D55: 8 | E55: =_xlfn.MAXIFS($J$5:$J$50,$A$5:$A$50,A55) | F55: =COUNTIFS($A$5:$A$50,A55,$L$5:$L$50,"NON")
A56: VMC 3 | B56: Centre ouest : déchets, san., ménage, lingerie | C56: =SUMIFS($F$5:$F$50,$A$5:$A$50,A56,$C$5:$C$50,"Raccord caisson") | D56: 7 | E56: =_xlfn.MAXIFS($J$5:$J$50,$A$5:$A$50,A56) | F56: =COUNTIFS($A$5:$A$50,A56,$L$5:$L$50,"NON")
A57: VMC 4 | B57: Centre est : office R+1, san., WC résidents, ménage RDC | C57: =SUMIFS($F$5:$F$50,$A$5:$A$50,A57,$C$5:$C$50,"Raccord caisson") | D57: 8 | E57: =_xlfn.MAXIFS($J$5:$J$50,$A$5:$A$50,A57) | F57: =COUNTIFS($A$5:$A$50,A57,$L$5:$L$50,"NON")
A58: VMC 5 | B58: Sud RDC : local déchets, nettoyage matériel | C58: =SUMIFS($F$5:$F$50,$A$5:$A$50,A58,$C$5:$C$50,"Raccord caisson") | D58: 2 | E58: =_xlfn.MAXIFS($J$5:$J$50,$A$5:$A$50,A58) | F58: =COUNTIFS($A$5:$A$50,A58,$L$5:$L$50,"NON")
A59: VMC 6 | B59: San. R+1 aile est | C59: =SUMIFS($F$5:$F$50,$A$5:$A$50,A59,$C$5:$C$50,"Raccord caisson") | D59: 1 | E59: =_xlfn.MAXIFS($J$5:$J$50,$A$5:$A$50,A59) | F59: =COUNTIFS($A$5:$A$50,A59,$L$5:$L$50,"NON")
A61: • 6 caissons C4 en toiture (VMC 5 sur la terrasse basse du RDC). Rejets à plus de 8 m des prises d'air neuf des CTA.
A62: • Gaines rigides partout (pas de flexible) ; antennes 200 × 60 jusqu'aux bouches ALYZE S (non listées ici).
A63: • Débit total extrait : 3 090 m³/h pour 46 bouches. Compensation : grilles de transfert pour offices et tisanerie (450 m³/h), détalonnage ailleurs.

Sheet Branches 27-10
A1: Branches ajoutées le 27/10/2026 pour raccorder les 31 dernières bouches
A2: Gaines plates de 60 mm de haut : seule hauteur qui passe au-dessus des troncs CTA 5 dans le plénum (0,57 m sous dalle). Vitesse maxi : onglet « Hypothèses » (CCTP § 2.2.5).
A4: CTA | B4: Réseau | C4: Niveau | D4: Tronçon | E4: Débit (m³/h) | F4: Largeur (mm) | G4: Hauteur (mm) | H4: Section (m²) | I4: Vitesse (m/s) | J4: Vitesse maxi CCTP (m/s) | K4: Conforme ?
A5: CTA 5 | B5: Soufflage | C5: RDC | D5: Famille (B344) — 400 × 60 depuis le 28/10 (montée de 1 m restée en 300 × 60) | E5: 234 | F5: 400 | G5: 60 | H5: =F5*G5/1000000 | I5: =ROUND(E5/3600/H5,2) | J5: =LOOKUP(E5,Hypothèses!$A$6:$A$16,Hypothèses!$C$6:$C$16) | K5: =IF(I5<=J5,"oui","NON")
A6: CTA 5 | B6: Soufflage | C6: RDC | D6: Atelier (B386) | E6: 90 | F6: 200 | G6: 60 | H6: =F6*G6/1000000 | I6: =ROUND(E6/3600/H6,2) | J6: =LOOKUP(E6,Hypothèses!$A$6:$A$16,Hypothèses!$C$6:$C$16) | K6: =IF(I6<=J6,"oui","NON")
A7: CTA 5 | B7: Soufflage | C7: RDC | D7: Bureau mutualisé (B335) | E7: 50 | F7: 200 | G7: 60 | H7: =F7*G7/1000000 | I7: =ROUND(E7/3600/H7,2) | J7: =LOOKUP(E7,Hypothèses!$A$6:$A$16,Hypothèses!$C$6:$C$16) | K7: =IF(I7<=J7,"oui","NON")
A8: CTA 5 | B8: Reprise | C8: RDC | D8: Accueil (B355) | E8: 50 | F8: 200 | G8: 60 | H8: =F8*G8/1000000 | I8: =ROUND(E8/3600/H8,2) | J8: =LOOKUP(E8,Hypothèses!$A$6:$A$16,Hypothèses!$C$6:$C$16) | K8: =IF(I8<=J8,"oui","NON")
A9: CTA 5 | B9: Reprise | C9: RDC | D9: Aile nord RDC (B395, B401) — 350 × 60 depuis le 28/10 (2,7 m restés en 300 × 60 avant B395) | E9: 198 | F9: 350 | G9: 60 | H9: =F9*G9/1000000 | I9: =ROUND(E9/3600/H9,2) | J9: =LOOKUP(E9,Hypothèses!$A$6:$A$16,Hypothèses!$C$6:$C$16) | K9: =IF(I9<=J9,"oui","NON")
A10: CTA 5 | B10: Soufflage | C10: Étage | D10: Salons ouest (B371, B372) | E10: 726 | F10: 1000 | G10: 60 | H10: =F10*G10/1000000 | I10: =ROUND(E10/3600/H10,2) | J10: =LOOKUP(E10,Hypothèses!$A$6:$A$16,Hypothèses!$C$6:$C$16) | K10: =IF(I10<=J10,"oui","NON")
A11: CTA 5 | B11: Soufflage | C11: Étage | D11: Salon est (B406) | E11: 352 | F11: 650 | G11: 60 | H11: =F11*G11/1000000 | I11: =ROUND(E11/3600/H11,2) | J11: =LOOKUP(E11,Hypothèses!$A$6:$A$16,Hypothèses!$C$6:$C$16) | K11: =IF(I11<=J11,"oui","NON")
A12: CTA 5 | B12: Reprise | C12: Étage | D12: Aile nord étage, jusqu'à B402 — 800 × 60 depuis le 28/10 | E12: 548 | F12: 800 | G12: 60 | H12: =F12*G12/1000000 | I12: =ROUND(E12/3600/H12,2) | J12: =LOOKUP(E12,Hypothèses!$A$6:$A$16,Hypothèses!$C$6:$C$16) | K12: =IF(I12<=J12,"oui","NON")
A13: CTA 5 | B13: Reprise | C13: Étage | D13: Aile nord, entre B402 et B403 (B403 + B405) | E13: 328 | F13: 600 | G13: 60 | H13: =F13*G13/1000000 | I13: =ROUND(E13/3600/H13,2) | J13: =LOOKUP(E13,Hypothèses!$A$6:$A$16,Hypothèses!$C$6:$C$16) | K13: =IF(I13<=J13,"oui","NON")
A14: CTA 5 | B14: Reprise | C14: Étage | D14: Couloir vers la détente (B405) | E14: 108 | F14: 600 | G14: 60 | H14: =F14*G14/1000000 | I14: =ROUND(E14/3600/H14,2) | J14: =LOOKUP(E14,Hypothèses!$A$6:$A$16,Hypothèses!$C$6:$C$16) | K14: =IF(I14<=J14,"oui","NON")
A15: CTA 5 | B15: Soufflage | C15: Étage | D15: Détente (B404) | E15: 108 | F15: 250 | G15: 60 | H15: =F15*G15/1000000 | I15: =ROUND(E15/3600/H15,2) | J15: =LOOKUP(E15,Hypothèses!$A$6:$A$16,Hypothèses!$C$6:$C$16) | K15: =IF(I15<=J15,"oui","NON")
A16: CTA 2 | B16: Reprise | C16: Étage | D16: Sdb (B369) | E16: 90 | F16: 200 | G16: 60 | H16: =F16*G16/1000000 | I16: =ROUND(E16/3600/H16,2) | J16: =LOOKUP(E16,Hypothèses!$A$6:$A$16,Hypothèses!$C$6:$C$16) | K16: =IF(I16<=J16,"oui","NON")
... A18: CTA 3 | B18: Soufflage | C18: Étage | D18: Chambre, bouche murale (B398) | E18: 90 | F18: 200 | G18: 60 | H18: =F18*G18/1000000 | I18: =ROUND(E18/3600/H18,2) | J18: =LOOKUP(E18,Hypothèses!$A$6:$A$16,Hypothèses!$C$6:$C$16) | K18: =IF(I18<=J18,"oui","NON")
A20: Corrigé le 28/10 : famille 400 × 60, aile nord RDC 350 × 60, aile nord étage 800 × 60 jusqu'à B402 (avec réductions). Restent au-dessus de la vitesse CCTP : 1 m de montée famille (300 × 60, 3,6 m/s) et 2,7 m avant B395 (300 × 60, 3,1 m/s).
