Workbook

Sheet Équipements
A1: EHPAD La Bassée – Nomenclature des équipements CVC
A2: Extrait de la maquette Revit EXE_RSP_CVC_MNT (17/10/2026). Même liste que la nomenclature Revit « CVC - Nomenclature des équipements », avec les infos des familles.
A4: Repère | B4: Équipement | C4: Fabricant | D4: Modèle | E4: Caractéristiques (CCTP) | F4: Source | G4: Niveau | H4: Local | I4: Posé à (m) | J4: Encombrement L×l×h (mm) | K4: Raccords | L4: Posé sur | M4: À vérifier | N4: ID Revit
A5: CTA 1 | B5: CTA 1 - aile Nord zone ouverte | C5: VIM | D5: CAD HR OPTIMAL C4 | E5: 2 520 m3/h | F5: CCTP lot 12 § 4.10 | G5: Toiture | H5: toiture terrasse | I5: 7.27 | J5: 1278 × 2260 × 1330 | K5: Rejet (600 x 400) Air neuf (600 x 400) Batterie change-over départ (DN 32) Soufflage (600 x 400) Batterie change-over retour (DN 32) Condensats (DN 32) Reprise (600 x 400) | L5: Socle CTA 1 | M5: Dimensions approximatives (2000x1100x1300 mm) : prendre la fiche VIM | N5: 1034386
A6: CTA 2 | B6: CTA 2 - aile Sud zone ouverte | C6: VIM | D6: CAD HR OPTIMAL C4 | E6: 2 330 m3/h | F6: CCTP lot 12 § 4.10 | G6: Toiture | H6: toiture terrasse | I6: 7.27 | J6: 2292 × 1312 × 1330 | K6: Batterie change-over retour (DN 32) Condensats (DN 32) Air neuf (600 x 400) Batterie change-over départ (DN 32) Soufflage (600 x 400) Reprise (600 x 400) Rejet (600 x 400) | L6: Socle CTA 2 | M6: Dimensions approximatives (2000x1100x1300 mm) : prendre la fiche VIM | N6: 1034387
A7: CTA 3 | B7: CTA 3 - aile Nord zone fermée | C7: VIM | D7: CAD HR OPTIMAL C4 | E7: 1 170 m3/h | F7: CCTP lot 12 § 4.10 | G7: Toiture | H7: toiture terrasse | I7: 7.27 | J7: 1278 × 2260 × 1330 | K7: Batterie change-over retour (DN 32) Condensats (DN 32) Soufflage (600 x 400) Reprise (600 x 400) Batterie change-over départ (DN 32) Air neuf (600 x 400) Rejet (600 x 400) | L7: Socle CTA 3 | M7: Dimensions approximatives (2000x1100x1300 mm) : prendre la fiche VIM | N7: 1034388
A8: CTA 4 | B8: CTA 4 - aile Sud zone fermée | C8: VIM | D8: CAD HR OPTIMAL C4 | E8: 1 170 m3/h | F8: CCTP lot 12 § 4.10 | G8: Toiture | H8: toiture terrasse | I8: 7.27 | J8: 1278 × 2260 × 1330 | K8: Condensats (DN 32) Rejet (600 x 400) Batterie change-over départ (DN 32) Air neuf (600 x 400) Batterie change-over retour (DN 32) Reprise (600 x 400) Soufflage (600 x 400) | L8: Socle CTA 4 | M8: Dimensions approximatives (2000x1100x1300 mm) : prendre la fiche VIM | N8: 1034389
A9: CTA 5 | B9: CTA 5 - zone commune | C9: VIM | D9: CAD O INTEGRAL | E9: 8 800 m3/h, débit variable, arrêt la nuit | F9: CCTP lot 12 § 4.11 | G9: Toiture | H9: toiture terrasse | I9: 7.27 | J9: 3760 × 1778 × 1930 | K9: Rejet (1000 x 600) Soufflage (1000 x 600) Reprise (1000 x 600) Condensats (DN 32) Air neuf (1000 x 600) Batterie change-over départ (DN 50) Batterie change-over retour (DN 50) | L9: Socle CTA 5 | M9: Dimensions approximatives (3500x1600x1900 mm) : prendre la fiche VIM | N9: 1034390
A10: ADOU | B10: Alcyo A5X | C10: Permo / Culligan | D10: Alcyo A5X | E10: Régénération par saumurage, -50 °TH, compteur DN50 | F10: CCTP lot 12 § 9.2.2 | G10: RDC | H10: chaufferie | I10: 0 | J10: 1095 × 520 × 1680 | K10: Entrée eau brute (DN 50) Sortie eau adoucie (DN 50) Égout régénération (DN 15) | M10: Dimensions approximatives (bouteille Ø340 x 1 680 mm, bac à sel 500 x 500 x 1 130 mm) | N10: 1038540
A11: B2000 ECS | B11: Préchauffage ECS 2000 L | C11: Non imposée | D11: 2000 L | E11: Préchauffage ECS par les PAC | F11: CCTP lot 12 § 4.5 | G11: RDC | H11: chaufferie | I11: 0.1 | J11: 1492 × 1300 × 2324 | K11: Piquage haut 1 (DN 50) Piquage bas 1 (DN 50) Piquage bas 2 (DN 50) Piquage haut 2 (DN 50) | L11: Socle B2000 1 | M11: Dimensions approximatives (Ø1300 isolé x 2300 mm) | N11: 1038537
A12: B2000 PRIM | B12: Stockage primaire 2000 L | C12: Non imposée | D12: 2000 L | E12: Stockage primaire ECS | F12: CCTP lot 12 § 4.5 | G12: RDC | H12: chaufferie | I12: 0.1 | J12: 1492 × 1300 × 2324 | K12: Piquage bas 2 (DN 50) Piquage bas 1 (DN 50) Piquage haut 2 (DN 50) Piquage haut 1 (DN 50) | L12: Socle B2000 2 | M12: Dimensions approximatives (Ø1300 isolé x 2300 mm) | N12: 1038538
A13: BT 1000 | B13: 1000 L | C13: Weishaupt | D13: WES 1000 WP/B | E13: Ballon tampon 1000 L en chaufferie | F13: CCTP lot 12 § 4.6.4 ; données Weishaupt | G13: RDC | H13: chaufferie | I13: 0.1 | J13: 990 × 1162 × 2153 | K13: Retour production (PAC) (DN 65) Retour distribution (DN 65) Départ production (PAC) (DN 65) Départ distribution (DN 65) | L13: Socle BT | M13: Raccordements à vérifier | N13: 1038534
A14: CH 1 | B14: 60 kW | C14: Weishaupt | D14: WTC-GW 60-B H | E14: 60 kW chaud, gaz naturel, condensation ; 2 unités | F14: CCTP lot 12 § 4.3.1 ; notice Weishaupt 83321401 | G14: RDC | H14: chaufferie | I14: 0.75 | J14: 500 × 485 × 1152 | K14: Départ chauffage (DN 32) Ventouse fumées / air Ø80/125 (Ø 125) Gaz naturel (DN 25) Condensats (siphon) (DN 25) Retour chauffage (DN 32) | M14: Dimensions 500x460x792 mm et raccordements à vérifier sur la notice | N14: 1038531
A15: CH 2 | B15: 60 kW | C15: Weishaupt | D15: WTC-GW 60-B H | E15: 60 kW chaud, gaz naturel, condensation ; 2 unités | F15: CCTP lot 12 § 4.3.1 ; notice Weishaupt 83321401 | G15: RDC | H15: chaufferie | I15: 0.75 | J15: 500 × 485 × 1152 | K15: Retour chauffage (DN 32) Ventouse fumées / air Ø80/125 (Ø 125) Gaz naturel (DN 25) Départ chauffage (DN 32) Condensats (siphon) (DN 25) | M15: Dimensions 500x460x792 mm et raccordements à vérifier sur la notice | N15: 1038532
A16: CIRC GLY | B16: D 65-150F | C16: Grundfos | D16: Magna3 D | E16: Circulateur double, circuits eau glycolée, pilotage 0-10 V | F16: CCTP lot 12 § 4.6.2 | G16: RDC | H16: chaufferie | I16: 1.1 | J16: 296 × 360 × 440 | K16: Aspiration (DN 65) Refoulement (DN 65) | M16: Dimensions approximatives (360x300x520 mm), à vérifier | N16: 1038544
A17: CIRC PAC | B17: D 65-80F | C17: Grundfos | D17: Magna3 D | E17: Circulateur double, circuits primaires PAC, pilotage 0-10 V | F17: CCTP lot 12 § 4.6.2 | G17: RDC | H17: chaufferie | I17: 1.1 | J17: 296 × 360 × 440 | K17: Aspiration (DN 65) Refoulement (DN 65) | M17: Dimensions approximatives (360x300x520 mm), à vérifier | N17: 1038545
A18: ECH ECS | B18: 100 kW | C18: Non imposée | D18: Échangeur à plaques | E18: 100 kW, régime 70/50 °C | F18: CCTP lot 12 § 4.5 | G18: RDC | H18: chaufferie | I18: 0 | J18: 630 × 470 × 900 | K18: Primaire sortie 50 °C (DN 50) Primaire entrée 70 °C (DN 50) Eau froide entrée (DN 50) ECS sortie (DN 50) | M18: Marque et dimensions à choisir | N18: 1038539
A19: P BECS | B19: IPL / SXS | C19: Wilo / Salmson | D19: IPL / SXS | E19: Double in-line ECS, 1 en secours, permutation automatique | F19: CCTP lot 12 § 9.4 | G19: RDC | H19: chaufferie | I19: 1 | J19: 300 × 270 × 450 | K19: Refoulement bouclage ECS (DN 50) Aspiration bouclage ECS (DN 50) | M19: Dimensions approximatives | N19: 1038541
A20: PAC 1 | B20: 35 kW | C20: Weishaupt | D20: WWP S 35 IDR | E20: 35 kW chaud, 40 kW froid, eau glycolée/eau, réversible ; 2 unités | F20: CCTP lot 12 § 4.6 | G20: RDC | H20: pac | I20: 0.1 | J20: 808 × 663 × 1252 | K20: Captage entrée (eau glycolée) (DN 40) Retour chauffage / rafraîchissement (DN 40) Captage sortie (eau glycolée) (DN 40) Départ chauffage / rafraîchissement (DN 40) | L20: Socle PAC 1 | M20: Dimensions APPROXIMATIVES (800x650x1100 mm) : aucune donnée fabricant trouvée | N20: 1038529
A21: PAC 2 | B21: 35 kW | C21: Weishaupt | D21: WWP S 35 IDR | E21: 35 kW chaud, 40 kW froid, eau glycolée/eau, réversible ; 2 unités | F21: CCTP lot 12 § 4.6 | G21: RDC | H21: pac | I21: 0.1 | J21: 808 × 663 × 1252 | K21: Captage sortie (eau glycolée) (DN 40) Captage entrée (eau glycolée) (DN 40) Départ chauffage / rafraîchissement (DN 40) Retour chauffage / rafraîchissement (DN 40) | L21: Socle PAC 2 | M21: Dimensions APPROXIMATIVES (800x650x1100 mm) : aucune donnée fabricant trouvée | N21: 1038530
A22: RA SAS | B22: SR M-200-H3 | C22: Biddle | D22: SR M-200-H3 | E22: Largeur 2000 mm, batterie chaude 30,8 kW | F22: CCTP lot 12 § 4.9.2 | G22: RDC | H22: sas | I22: 2.48 | J22: 752 × 2044 × 370 | K22: Batterie retour (DN 25) Batterie aller (DN 25) | M22: Profondeur et hauteur approximatives | N22: 1038546
A23: VE 1 | B23: PNU | C23: Pneumatex | D23: PNU | E23: Vase sous pression d azote avec vessie ; 2 unités | F23: CCTP lot 12 § 4.3.3 | G23: RDC | H23: chaufferie | I23: 0 | J23: 500 × 544 × 895 | K23: Raccordement vase (DN 25) | M23: Volume non donné au CCTP : taille (Ø500x900) à dimensionner | N23: 1038542
A24: VE 2 | B24: PNU | C24: Pneumatex | D24: PNU | E24: Vase sous pression d azote avec vessie ; 2 unités | F24: CCTP lot 12 § 4.3.3 | G24: RDC | H24: chaufferie | I24: 0 | J24: 500 × 544 × 895 | K24: Raccordement vase (DN 25) | M24: Volume non donné au CCTP : taille (Ø500x900) à dimensionner | N24: 1038543
A26: Socles
A27: Socle B2000 1 | B27: Socle 1500 x 1500 x 100 | E27: Socles à la charge du lot gros œuvre (chaudières, ballons ECS, CTA…) ; 1 massif distinct par appareil ; appareils à moteur sur plots ou matelas résilient | F27: CCTP lot 12 § 1.8.2 (gros œuvre), § 3.14.1 (socles et supports) | G27: RDC | H27: chaufferie | I27: 0 | J27: 1500 × 1500 × 100 | L27: supporte B2000 ECS | M27: Dimensions du socle à caler sur la fiche fabricant de l’appareil | N27: 1038535
A28: Socle B2000 2 | B28: Socle 1500 x 1500 x 100 | E28: Socles à la charge du lot gros œuvre (chaudières, ballons ECS, CTA…) ; 1 massif distinct par appareil ; appareils à moteur sur plots ou matelas résilient | F28: CCTP lot 12 § 1.8.2 (gros œuvre), § 3.14.1 (socles et supports) | G28: RDC | H28: chaufferie | I28: 0 | J28: 1500 × 1500 × 100 | L28: supporte B2000 PRIM | M28: Dimensions du socle à caler sur la fiche fabricant de l’appareil | N28: 1038536
A29: Socle BT | B29: Socle 1200 x 1200 x 100 | E29: Socles à la charge du lot gros œuvre (chaudières, ballons ECS, CTA…) ; 1 massif distinct par appareil ; appareils à moteur sur plots ou matelas résilient | F29: CCTP lot 12 § 1.8.2 (gros œuvre), § 3.14.1 (socles et supports) | G29: RDC | H29: chaufferie | I29: 0 | J29: 1200 × 1200 × 100 | L29: supporte BT 1000 | M29: Dimensions du socle à caler sur la fiche fabricant de l’appareil | N29: 1038533
A30: Socle CTA 1 | B30: Socle CTA C4 2300 x 1400 | E30: 1 massif distinct par appareil, matériel scellé sur son socle ; plots anti-vibratiles disposés symétriquement à la périphérie (ou matelas résilient) sur un pré-socle d’environ 5 cm de mêmes dimensions ; en toiture, hauteur au-dessus de l’étanchéité limitée à 0,40 m ; relevés béton et d’étanchéité par les lots GO / couverture, couvertine galva 15/10 et surtoiture par le lot CVC | F30: CCTP lot 12 § 3.14.1 (socles et supports), § 1.8.2 (socles à la charge du GO), § 1.9.2 (équipements en toiture), § 3.9.1 (CTA sur socle) | G30: Toiture | H30: toiture terrasse | I30: 7.02 | J30: 1400 × 2300 × 250 | L30: supporte CTA 1 | M30: Masse et dimensions du massif à calculer avec le poids de la CTA (fiche VIM) ; nombre et type de plots à dimensionner (note de calcul des supports anti-vibratiles) | N30: 1036124
A31: Socle CTA 2 | B31: Socle CTA C4 2300 x 1400 | E31: 1 massif distinct par appareil, matériel scellé sur son socle ; plots anti-vibratiles disposés symétriquement à la périphérie (ou matelas résilient) sur un pré-socle d’environ 5 cm de mêmes dimensions ; en toiture, hauteur au-dessus de l’étanchéité limitée à 0,40 m ; relevés béton et d’étanchéité par les lots GO / couverture, couvertine galva 15/10 et surtoiture par le lot CVC | F31: CCTP lot 12 § 3.14.1 (socles et supports), § 1.8.2 (socles à la charge du GO), § 1.9.2 (équipements en toiture), § 3.9.1 (CTA sur socle) | G31: Toiture | H31: toiture terrasse | I31: 7.02 | J31: 2370 × 1518 × 250 | L31: supporte CTA 2 | M31: Masse et dimensions du massif à calculer avec le poids de la CTA (fiche VIM) ; nombre et type de plots à dimensionner (note de calcul des supports anti-vibratiles) | N31: 1036125
A32: Socle CTA 3 | B32: Socle CTA C4 2300 x 1400 | E32: 1 massif distinct par appareil, matériel scellé sur son socle ; plots anti-vibratiles disposés symétriquement à la périphérie (ou matelas résilient) sur un pré-socle d’environ 5 cm de mêmes dimensions ; en toiture, hauteur au-dessus de l’étanchéité limitée à 0,40 m ; relevés béton et d’étanchéité par les lots GO / couverture, couvertine galva 15/10 et surtoiture par le lot CVC | F32: CCTP lot 12 § 3.14.1 (socles et supports), § 1.8.2 (socles à la charge du GO), § 1.9.2 (équipements en toiture), § 3.9.1 (CTA sur socle) | G32: Toiture | H32: toiture terrasse | I32: 7.02 | J32: 1400 × 2300 × 250 | L32: supporte CTA 3 | M32: Masse et dimensions du massif à calculer avec le poids de la CTA (fiche VIM) ; nombre et type de plots à dimensionner (note de calcul des supports anti-vibratiles) | N32: 1036126
A33: Socle CTA 4 | B33: Socle CTA C4 2300 x 1400 | E33: 1 massif distinct par appareil, matériel scellé sur son socle ; plots anti-vibratiles disposés symétriquement à la périphérie (ou matelas résilient) sur un pré-socle d’environ 5 cm de mêmes dimensions ; en toiture, hauteur au-dessus de l’étanchéité limitée à 0,40 m ; relevés béton et d’étanchéité par les lots GO / couverture, couvertine galva 15/10 et surtoiture par le lot CVC | F33: CCTP lot 12 § 3.14.1 (socles et supports), § 1.8.2 (socles à la charge du GO), § 1.9.2 (équipements en toiture), § 3.9.1 (CTA sur socle) | G33: Toiture | H33: toiture terrasse | I33: 7.02 | J33: 1400 × 2300 × 250 | L33: supporte CTA 4 | M33: Masse et dimensions du massif à calculer avec le poids de la CTA (fiche VIM) ; nombre et type de plots à dimensionner (note de calcul des supports anti-vibratiles) | N33: 1036127
A34: Socle CTA 5 | B34: Socle CTA 5 3800 x 1900 | E34: 1 massif distinct par appareil, matériel scellé sur son socle ; plots anti-vibratiles disposés symétriquement à la périphérie (ou matelas résilient) sur un pré-socle d’environ 5 cm de mêmes dimensions ; en toiture, hauteur au-dessus de l’étanchéité limitée à 0,40 m ; relevés béton et d’étanchéité par les lots GO / couverture, couvertine galva 15/10 et surtoiture par le lot CVC | F34: CCTP lot 12 § 3.14.1 (socles et supports), § 1.8.2 (socles à la charge du GO), § 1.9.2 (équipements en toiture), § 3.9.1 (CTA sur socle) | G34: Toiture | H34: toiture terrasse | I34: 7.02 | J34: 3800 × 1900 × 250 | L34: supporte CTA 5 | M34: Masse et dimensions du massif à calculer avec le poids de la CTA (fiche VIM) ; nombre et type de plots à dimensionner (note de calcul des supports anti-vibratiles) | N34: 1036128
A35: Socle PAC 1 | B35: Socle 900 x 700 x 100 + résilient | E35: Socles à la charge du lot gros œuvre (chaudières, ballons ECS, CTA…) ; 1 massif distinct par appareil ; appareils à moteur sur plots ou matelas résilient | F35: CCTP lot 12 § 1.8.2 (gros œuvre), § 3.14.1 (socles et supports) | G35: RDC | H35: pac | I35: 0 | J35: 900 × 700 × 100 | L35: supporte PAC 1 | M35: Dimensions du socle à caler sur la fiche fabricant de l’appareil | N35: 1038527
A36: Socle PAC 2 | B36: Socle 900 x 700 x 100 + résilient | E36: Socles à la charge du lot gros œuvre (chaudières, ballons ECS, CTA…) ; 1 massif distinct par appareil ; appareils à moteur sur plots ou matelas résilient | F36: CCTP lot 12 § 1.8.2 (gros œuvre), § 3.14.1 (socles et supports) | G36: RDC | H36: pac | I36: 0 | J36: 900 × 700 × 100 | L36: supporte PAC 2 | M36: Dimensions du socle à caler sur la fiche fabricant de l’appareil | N36: 1038528
A38: Nombre d'équipements (hors socles) : | D38: =COUNTA(A5:A24) -> 20

Sheet Quantités gaines
A1: Quantités de gaines rectangulaires – réseaux principaux
A2: Gaines rigides en tôle galvanisée (pas de flexible). Longueurs lues dans Revit. Surface de tôle = périmètre × longueur (sans les raccords).
A4: Réseau | B4: Système | C4: Section L × H (mm) | D4: Nb de gaines | E4: Longueur (m) | F4: Périmètre (m) | G4: Surface de tôle (m²)
A5: CTA 1 | B5: Reprise | C5: 450 × 300 | D5: 2 | E5: 2.22 | F5: =2*(450+300)/1000 -> 1.5 | G5: =E5*F5 -> 3.33
A6: CTA 1 | B6: Reprise | C6: 350 × 250 | D6: 1 | E6: 2.5 | F6: =2*(350+250)/1000 -> 1.2 | G6: =E6*F6 -> 3
A7: CTA 1 | B7: Reprise | C7: 250 × 250 | D7: 2 | E7: 12.5 | F7: =2*(250+250)/1000 -> 1 | G7: =E7*F7 -> 12.5
A8: CTA 1 | B8: Reprise | C8: 200 × 250 | D8: 4 | E8: 41.05 | F8: =2*(200+250)/1000 -> 0.9 | G8: =E8*F8 -> 36.945
A9: CTA 1 | B9: Soufflage | C9: 450 × 300 | D9: 2 | E9: 0.93 | F9: =2*(450+300)/1000 -> 1.5 | G9: =E9*F9 -> 1.395
A10: CTA 1 | B10: Soufflage | C10: 350 × 250 | D10: 1 | E10: 2.5 | F10: =2*(350+250)/1000 -> 1.2 | G10: =E10*F10 -> 3
A11: CTA 1 | B11: Soufflage | C11: 250 × 250 | D11: 2 | E11: 12.5 | F11: =2*(250+250)/1000 -> 1 | G11: =E11*F11 -> 12.5
A12: CTA 1 | B12: Soufflage | C12: 200 × 250 | D12: 4 | E12: 41.09 | F12: =2*(200+250)/1000 -> 0.9 | G12: =E12*F12 -> 36.981
A13: CTA 2 | B13: Reprise | C13: 450 × 300 | D13: 3 | E13: 3.1 | F13: =2*(450+300)/1000 -> 1.5 | G13: =E13*F13 -> 4.65
A14: CTA 2 | B14: Reprise | C14: 350 × 250 | D14: 1 | E14: 2.18 | F14: =2*(350+250)/1000 -> 1.2 | G14: =E14*F14 -> 2.616
A15: CTA 2 | B15: Reprise | C15: 200 × 250 | D15: 4 | E15: 49.24 | F15: =2*(200+250)/1000 -> 0.9 | G15: =E15*F15 -> 44.316
A16: CTA 2 | B16: Soufflage | C16: 450 × 300 | D16: 3 | E16: 2.93 | F16: =2*(450+300)/1000 -> 1.5 | G16: =E16*F16 -> 4.395
A17: CTA 2 | B17: Soufflage | C17: 350 × 250 | D17: 1 | E17: 2.18 | F17: =2*(350+250)/1000 -> 1.2 | G17: =E17*F17 -> 2.616
A18: CTA 2 | B18: Soufflage | C18: 200 × 250 | D18: 4 | E18: 49.24 | F18: =2*(200+250)/1000 -> 0.9 | G18: =E18*F18 -> 44.316
A19: CTA 3 | B19: Reprise | C19: 300 × 250 | D19: 2 | E19: 6.31 | F19: =2*(300+250)/1000 -> 1.1 | G19: =E19*F19 -> 6.941
A20: CTA 3 | B20: Reprise | C20: 250 × 250 | D20: 1 | E20: 1.45 | F20: =2*(250+250)/1000 -> 1 | G20: =E20*F20 -> 1.45
A21: CTA 3 | B21: Reprise | C21: 200 × 250 | D21: 2 | E21: 25.97 | F21: =2*(200+250)/1000 -> 0.9 | G21: =E21*F21 -> 23.373
A22: CTA 3 | B22: Soufflage | C22: 300 × 250 | D22: 2 | E22: 5.11 | F22: =2*(300+250)/1000 -> 1.1 | G22: =E22*F22 -> 5.621
A23: CTA 3 | B23: Soufflage | C23: 250 × 250 | D23: 1 | E23: 1.45 | F23: =2*(250+250)/1000 -> 1 | G23: =E23*F23 -> 1.45
A24: CTA 3 | B24: Soufflage | C24: 200 × 250 | D24: 2 | E24: 26.03 | F24: =2*(200+250)/1000 -> 0.9 | G24: =E24*F24 -> 23.427
A25: CTA 4 | B25: Reprise | C25: 300 × 250 | D25: 3 | E25: 5.08 | F25: =2*(300+250)/1000 -> 1.1 | G25: =E25*F25 -> 5.588
A26: CTA 4 | B26: Reprise | C26: 250 × 250 | D26: 1 | E26: 4.88 | F26: =2*(250+250)/1000 -> 1 | G26: =E26*F26 -> 4.88
A27: CTA 4 | B27: Reprise | C27: 200 × 250 | D27: 2 | E27: 20.8 | F27: =2*(200+250)/1000 -> 0.9 | G27: =E27*F27 -> 18.72
A28: CTA 4 | B28: Soufflage | C28: 300 × 250 | D28: 3 | E28: 3.89 | F28: =2*(300+250)/1000 -> 1.1 | G28: =E28*F28 -> 4.279
A29: CTA 4 | B29: Soufflage | C29: 250 × 250 | D29: 1 | E29: 4.88 | F29: =2*(250+250)/1000 -> 1 | G29: =E29*F29 -> 4.88
A30: CTA 4 | B30: Soufflage | C30: 200 × 250 | D30: 2 | E30: 20.8 | F30: =2*(200+250)/1000 -> 0.9 | G30: =E30*F30 -> 18.72
A31: CTA 5 | B31: Reprise | C31: 700 × 400 | D31: 3 | E31: 5.57 | F31: =2*(700+400)/1000 -> 2.2 | G31: =E31*F31 -> 12.254
A32: CTA 5 | B32: Reprise | C32: 700 × 300 | D32: 1 | E32: 2.31 | F32: =2*(700+300)/1000 -> 2 | G32: =E32*F32 -> 4.62
A33: CTA 5 | B33: Reprise | C33: 500 × 400 | D33: 2 | E33: 5.71 | F33: =2*(500+400)/1000 -> 1.8 | G33: =E33*F33 -> 10.278
A34: CTA 5 | B34: Reprise | C34: 650 × 300 | D34: 1 | E34: 7.64 | F34: =2*(650+300)/1000 -> 1.9 | G34: =E34*F34 -> 14.516
A35: CTA 5 | B35: Reprise | C35: 600 × 300 | D35: 1 | E35: 3.42 | F35: =2*(600+300)/1000 -> 1.8 | G35: =E35*F35 -> 6.156
A36: CTA 5 | B36: Reprise | C36: 550 × 300 | D36: 1 | E36: 10.77 | F36: =2*(550+300)/1000 -> 1.7 | G36: =E36*F36 -> 18.309
A37: CTA 5 | B37: Reprise | C37: 500 × 300 | D37: 1 | E37: 12.46 | F37: =2*(500+300)/1000 -> 1.6 | G37: =E37*F37 -> 19.936
A38: CTA 5 | B38: Reprise | C38: 350 × 300 | D38: 1 | E38: 20.97 | F38: =2*(350+300)/1000 -> 1.3 | G38: =E38*F38 -> 27.261
A39: CTA 5 | B39: Reprise | C39: 350 × 250 | D39: 1 | E39: 8.92 | F39: =2*(350+250)/1000 -> 1.2 | G39: =E39*F39 -> 10.704
A40: CTA 5 | B40: Reprise | C40: 200 × 250 | D40: 7 | E40: 66.27 | F40: =2*(200+250)/1000 -> 0.9 | G40: =E40*F40 -> 59.643
A41: CTA 5 | B41: Soufflage | C41: 700 × 400 | D41: 3 | E41: 3.42 | F41: =2*(700+400)/1000 -> 2.2 | G41: =E41*F41 -> 7.524
...

Sheet Bilan conflits
A1: Bilan de la détection de conflits
A2: Compté à partir de l'onglet Conflits (formules NB.SI). En jaune : vrais problèmes à corriger dans la maquette.
A4: Type | B4: Nombre | C4: À faire
A5: Gaine verticale dans un mur | B5: =COUNTIF(Conflits!$B$5:$B$230,A5) -> 3 | C5: À corriger : déplacer la gaine technique.
A6: Gaine contre poutre retombante | B6: =COUNTIF(Conflits!$B$5:$B$230,A6) -> 19 | C6: À corriger : contourner ou réservation validée par la structure.
A7: Gaine contre dalle | B7: =COUNTIF(Conflits!$B$5:$B$230,A7) -> 6 | C7: À corriger : dévoyer.
A8: Gaine contre poutre | B8: =COUNTIF(Conflits!$B$5:$B$230,A8) -> 14 | C8: À corriger : descendre les gaines de ~10 cm.
A9: Trémie (gaine verticale) | B9: =COUNTIF(Conflits!$B$5:$B$230,A9) -> 24 | C9: Normal : trémies à réserver.
A10: Traversée de voile béton | B10: =COUNTIF(Conflits!$B$5:$B$230,A10) -> 54 | C10: Normal : réservations à demander.
A11: Traversée de cloison | B11: =COUNTIF(Conflits!$B$5:$B$230,A11) -> 106 | C11: Normal : percements + calfeutrements.
A12: Total | B12: =SUM(B5:B11) -> 226
A14: Autres contrôles :
A15: • Rideau d'air RA SAS contre le faux plafond non démontable du sas : encastré à 2,48 m, réservation + trappe à demander (1 conflit gardé exprès).
A16: • Gaines entre elles : 47 contacts, surtout aux pieds des gaines techniques (raccords à finir) et aux départs d'antennes où soufflage et reprise se croisent (une des deux à faire passer dessous).

Sheet Conflits
A1: Détection de conflits – gaines CVC contre archi et structure
A2: Recherche faite dans Revit (intersection des volumes) entre nos gaines et les maquettes liées DCE_ARC_MNT et DCE_STR_MNT_corrige, le 17/10/2026.
A4: N° | B4: Type | C4: Gaine (réseau, partie) | D4: Section (mm) | E4: Élément touché | F4: Maquette | G4: X | H4: Y | I4: Z (m) | J4: Ce qu'on propose | K4: ID gaine | L4: ID élément
A5: 1 | B5: Gaine verticale dans un mur | C5: CTA 3 reprise - gaine technique verticale (1170 m3/h) | D5: 300 × 250 | E5: GAINE DF TOITURE | F5: DCE_ARC_MNT | G5: -51.55 | H5: 37.19 | I5: 7.22 | J5: À déplacer : la gaine technique tombe dans un mur ou une gaine de désenfumage. | K5: 1040179 | L5: 5836793
A6: 2 | B6: Gaine verticale dans un mur | C6: CTA 3 soufflage - gaine technique verticale (1170 m3/h) | D6: 300 × 250 | E6: GAINE DF TOITURE | F6: DCE_ARC_MNT | G6: -51.54 | H6: 37.72 | I6: 7.18 | J6: À déplacer : la gaine technique tombe dans un mur ou une gaine de désenfumage. | K6: 1040165 | L6: 5836807
A7: 3 | B7: Gaine verticale dans un mur | C7: CTA 5 soufflage - gaine technique verticale (4093 m3/h) | D7: 500 × 400 | E7: CLOISON 100mm ISOLEE | F7: DCE_ARC_MNT | G7: -65.94 | H7: 38.22 | I7: 3.01 | J7: À déplacer : la gaine technique tombe dans un mur ou une gaine de désenfumage. | K7: 1040223 | L7: 5089635
A8: 4 | B8: Gaine contre poutre retombante | C8: CTA 5 reprise - N00 - 129 m3/h - tronçons CTA5-29 | D8: 200 × 250 | E8: POU-BN-BETON-20x20ht | F8: DCE_STR_MNT | G8: -31.65 | H8: 35.98 | I8: 2.92 | J8: Retombée trop grande : passer à côté, ou réservation dans la poutre (à valider par la structure). | K8: 1040319 | L8: 1514874
A9: 5 | B9: Gaine contre poutre retombante | C9: CTA 5 reprise - N00 - 129 m3/h - tronçons CTA5-29 | D9: 200 × 250 | E9: POU-BETON-20x70ht | F9: DCE_STR_MNT | G9: -31.65 | H9: 27.94 | I9: 2.86 | J9: Retombée trop grande : passer à côté, ou réservation dans la poutre (à valider par la structure). | K9: 1040319 | L9: 1610188
A10: 6 | B10: Gaine contre poutre retombante | C10: CTA 5 reprise - N00 - 211 m3/h - tronçons CTA5-25 | D10: 200 × 250 | E10: POU-BN-BETON-20x20ht | F10: DCE_STR_MNT | G10: -34.96 | H10: 36.87 | I10: 2.92 | J10: Retombée trop grande : passer à côté, ou réservation dans la poutre (à valider par la structure). | K10: 1040311 | L10: 1514923
A11: 7 | B11: Gaine contre poutre retombante | C11: CTA 5 reprise - N00 - 211 m3/h - tronçons CTA5-25 | D11: 200 × 250 | E11: POU-BETON-20x50ht | F11: DCE_STR_MNT | G11: -34.71 | H11: 42.58 | I11: 2.92 | J11: Retombée trop grande : passer à côté, ou réservation dans la poutre (à valider par la structure). | K11: 1040311 | L11: 1587124
A12: 8 | B12: Gaine contre poutre retombante | C12: CTA 5 reprise - N00 - 211 m3/h - tronçons CTA5-26 | D12: 200 × 250 | E12: POU-BETON-20x55ht | F12: DCE_STR_MNT | G12: -33.8 | H12: 55.96 | I12: 2.9 | J12: Retombée trop grande : passer à côté, ou réservation dans la poutre (à valider par la structure). | K12: 1040313 | L12: 1495898
A13: 9 | B13: Gaine contre poutre retombante | C13: CTA 5 reprise - N00 - 211 m3/h - tronçons CTA5-26 | D13: 200 × 250 | E13: POU-BETON-20x147ht | F13: DCE_STR_MNT | G13: -33.8 | H13: 47.62 | I13: 2.86 | J13: Retombée trop grande : passer à côté, ou réservation dans la poutre (à valider par la structure). | K13: 1040313 | L13: 1654584
A14: 10 | B14: Gaine contre poutre retombante | C14: CTA 5 reprise - N00 - 2856 m3/h - tronçons CTA5-19, CTA5-20, CTA5-21, CTA5-22 | D14: 500 × 300 | E14: POU-BETON-70x70ht | F14: DCE_STR_MNT | G14: -24.23 | H14: 36.01 | I14: 2.86 | J14: Retombée trop grande : passer à côté, ou réservation dans la poutre (à valider par la structure). | K14: 1040297 | L14: 1492230
A15: 11 | B15: Gaine contre poutre retombante | C15: CTA 5 reprise - N00 - 2856 m3/h - tronçons CTA5-19, CTA5-20, CTA5-21, CTA5-22 | D15: 500 × 300 | E15: POU-BN-BETON-20x20ht | F15: DCE_STR_MNT | G15: -31.39 | H15: 36.01 | I15: 2.93 | J15: Retombée trop grande : passer à côté, ou réservation dans la poutre (à valider par la structure). | K15: 1040297 | L15: 1514874
A16: 12 | B16: Gaine contre poutre retombante | C16: CTA 5 reprise - N00 - 2856 m3/h - tronçons CTA5-19, CTA5-20, CTA5-21, CTA5-22 | D16: 500 × 300 | E16: POU-BETON-20x70ht | F16: DCE_STR_MNT | G16: -34.45 | H16: 36.01 | I16: 2.86 | J16: Retombée trop grande : passer à côté, ou réservation dans la poutre (à valider par la structure). | K16: 1040297 | L16: 1654058
... A230: 226 | B230: Traversée de cloison | C230: CTA 5 soufflage - N01 - 706 m3/h - tronçons CTA5-43, CTA5-44 | D230: 200 × 250 | E230: CLOISON 100mm ISOLEE | F230: DCE_ARC_MNT | G230: -31.86 | H230: 38.07 | I230: 6.22 | J230: Normal : percement + calfeutrement ; clapet coupe-feu si cloison CF. | K230: 1040249 | L230: 5082966
